### AI Lover Log - Last updated at 2025-10-07T23:38:31.766155 ###

2025-10-07 22:39:02 - [INFO] - [512280345618546699] [自我修正] ✅ 修正流程成功，正在重新驗證...
2025-10-07 22:39:02 - [ERROR] - [512280345618546699] [自我修正] 🔥 自我修正流程最終失敗: 2 validation errors for SceneLocationExtraction
has_explicit_location
  Input should be a valid boolean, unable to interpret input [type=bool_parsing, input_value='{has_explicit_location}', input_type=str]
    For further information visit https://errors.pydantic.dev/2.8/v/bool_parsing
location_path
  Input should be a valid list [type=list_type, input_value='{location_path}', input_type=str]
    For further information visit https://errors.pydantic.dev/2.8/v/list_type
Traceback (most recent call last):
  File "D:\DINO\SD\ComfyUI\personal_server\ai_lover_service\src\ai_core.py", line 1767, in ainvoke_with_rotation
    return output_schema.model_validate(json.loads(corrected_clean_json_str))
  File "C:\Users\USER\AppData\Local\Programs\Python\Python310\lib\site-packages\pydantic\main.py", line 568, in model_validate
    return cls.__pydantic_validator__.validate_python(
pydantic_core._pydantic_core.ValidationError: 2 validation errors for SceneLocationExtraction
has_explicit_location
  Input should be a valid boolean, unable to interpret input [type=bool_parsing, input_value='{has_explicit_location}', input_type=str]
    For further information visit https://errors.pydantic.dev/2.8/v/bool_parsing
location_path
  Input should be a valid list [type=list_type, input_value='{location_path}', input_type=str]
    For further information visit https://errors.pydantic.dev/2.8/v/list_type
2025-10-07 22:39:02 - [ERROR] - [512280345618546699] (_resolve_and_save) 在創建 '愛莉莎' 時發生錯誤: Expecting property name enclosed in double quotes: line 2 column 29 (char 30)
Traceback (most recent call last):
  File "D:\DINO\SD\ComfyUI\personal_server\ai_lover_service\src\ai_core.py", line 984, in _resolve_and_save
    location_result = await self.ainvoke_with_rotation(
  File "D:\DINO\SD\ComfyUI\personal_server\ai_lover_service\src\ai_core.py", line 1770, in ainvoke_with_rotation
    raise e
  File "D:\DINO\SD\ComfyUI\personal_server\ai_lover_service\src\ai_core.py", line 1738, in ainvoke_with_rotation
    return output_schema.model_validate(json.loads(clean_json_str))
  File "C:\Users\USER\AppData\Local\Programs\Python\Python310\lib\json\__init__.py", line 346, in loads
    return _default_decoder.decode(s)
  File "C:\Users\USER\AppData\Local\Programs\Python\Python310\lib\json\decoder.py", line 337, in decode
    obj, end = self.raw_decode(s, idx=_w(s, 0).end())
  File "C:\Users\USER\AppData\Local\Programs\Python\Python310\lib\json\decoder.py", line 353, in raw_decode
    obj, end = self.scan_once(s, idx)
json.decoder.JSONDecodeError: Expecting property name enclosed in double quotes: line 2 column 29 (char 30)
2025-10-07 22:39:03 - [INFO] - [512280345618546699] [LLM Success] Generation successful using model 'gemini-2.5-flash-lite' with API Key #0.
2025-10-07 22:39:03 - [INFO] - [512280345618546699] (_resolve_and_save) 正在創建新 LORE：'王城 > 皇家圖書館 > 安娜'
2025-10-07 22:39:04 - [INFO] - [512280345618546699] [LLM Success] Generation successful using model 'gemini-2.5-flash-lite' with API Key #0.
2025-10-07 22:39:04 - [INFO] - [512280345618546699] (_resolve_and_save) 正在創建新 LORE：'冰霜巨魔的洞穴 > 澤拉'
2025-10-07 22:39:04 - [INFO] - [512280345618546699] 後台創世流程結束，狀態鎖已釋放。
2025-10-07 22:50:02 - [INFO] - 正在加載核心 Cog (core_cog)...
2025-10-07 22:50:07 - [INFO] - ✅ 核心 Cog (core_cog) 已加載，並且所有持久化視圖已成功註冊。
2025-10-07 22:50:07 - [INFO] - ✅ 核心 Cog 加載成功。
2025-10-07 22:50:07 - [INFO] - 正在全域同步應用程式指令...
2025-10-07 22:50:08 - [INFO] - ✅ 指令已全域同步！
2025-10-07 22:50:08 - [INFO] - Discord Bot setup hook finished!
2025-10-07 22:50:10 - [INFO] - Logged in as AI#4450 (ID: 1358417100250808531)
2025-10-07 22:50:11 - [INFO] - 已成功發送啟動成功通知給管理員。
2025-10-07 22:50:23 - [INFO] - [512280345618546699] [Data Reset] 正在啟動使用者資料重置流程...
2025-10-07 22:50:24 - [INFO] - [512280345618546699] [Data Reset] 所有相關的資料庫記錄已成功刪除。
2025-10-07 22:50:24 - [INFO] - [512280345618546699] [Data Reset] 向量儲存目錄 'D:\DINO\SD\ComfyUI\personal_server\ai_lover_service\data\vector_stores\512280345618546699' 已成功刪除。
2025-10-07 22:50:24 - [INFO] - [512280345618546699] [Data Reset] 資料重置流程已全部完成。
2025-10-07 22:50:25 - [INFO] - [512280345618546699] (UI Event) Persistent 'StartSetupView' button clicked.
2025-10-07 22:50:31 - [INFO] - 使用者 512280345618546699 沒有活躍的 AI 實例，嘗試創建...
2025-10-07 22:50:31 - [INFO] - [512280345618546699] 處於設定流程中，即使資料庫無記錄，也創建一個臨時的記憶體實例。
2025-10-07 22:50:31 - [INFO] - [512280345618546699] 核心數據模板 'world_snapshot_template.txt' 已成功加載。
2025-10-07 22:50:31 - [INFO] - [512280345618546699] 核心協議 '00_supreme_directive.txt' 已成功加載。
2025-10-07 22:50:31 - [INFO] - ✅ [Embedding Loader] 檢測到本地模型路徑，正在嘗試從 'D:\DINO\SD\ComfyUI\personal_server\ai_lover_service\models\stella-base-zh-v2' 加載...
2025-10-07 22:50:40 - [INFO] - ✅ [Embedding Loader] 本地 Embedding 模型實例創建成功。
2025-10-07 22:50:40 - [INFO] - [512280345618546699] 所有輕量級前置資源已準備就緒 (RAG 創建已延遲)。
2025-10-07 22:50:40 - [INFO] - [512280345618546699] 接收到 profile 更新請求: ['world_settings']
2025-10-07 22:50:40 - [WARNING] - [512280345618546699] 在持久化更新時找不到使用者資料，將創建新記錄。
2025-10-07 22:50:40 - [INFO] - [512280345618546699] Profile 更新並持久化成功。
2025-10-07 22:50:42 - [INFO] - [512280345618546699] (UI Event) Persistent 'ContinueToUserSetupView' button clicked.
2025-10-07 22:50:49 - [INFO] - [512280345618546699] (UI Event) CharacterSettingsModal submitted for profile_type: 'user', is_setup_flow: True
2025-10-07 22:50:50 - [INFO] - [512280345618546699] 接收到 profile 更新請求: ['user_profile']
2025-10-07 22:50:50 - [INFO] - [512280345618546699] Profile 更新並持久化成功。
2025-10-07 22:50:53 - [INFO] - [512280345618546699] (UI Event) Persistent 'ContinueToAiSetupView' button clicked.
2025-10-07 22:51:07 - [INFO] - [512280345618546699] (UI Event) CharacterSettingsModal submitted for profile_type: 'ai', is_setup_flow: True
2025-10-07 22:51:07 - [INFO] - [512280345618546699] 接收到 profile 更新請求: ['ai_profile']
2025-10-07 22:51:07 - [INFO] - [512280345618546699] Profile 更新並持久化成功。
2025-10-07 22:51:09 - [INFO] - [512280345618546699] [創世流程] 檔案上傳開始，已設定 active_setups 狀態鎖。
2025-10-07 22:51:16 - [INFO] - [512280345618546699] (on_message) 偵測到用戶處於活躍的創世流程中，已忽略常規訊息 '...' 以防止競爭。
2025-10-07 22:51:18 - [INFO] - [512280345618546699] [創世流程 v67.0] 原生 Python 驅動的流程已啟動。
2025-10-07 22:51:18 - [INFO] - [512280345618546699] [後台創世] 步驟 1/5: 正在解析世界聖經並創建 LORE 骨架...
2025-10-07 22:51:18 - [INFO] - [512280345618546699] [數據入口-軌道B] 正在啟動 LORE 解析管線...
2025-10-07 22:51:18 - [INFO] - [512280345618546699] [LORE 解析] 已將世界聖經原文分割成 8 個文本塊進行處理。
2025-10-07 22:51:18 - [INFO] - [512280345618546699] [LORE 解析] 正在處理文本塊 1/8...
2025-10-07 22:51:18 - [INFO] - [512280345618546699] [LORE 解析 1-1/3] 正在嘗試【理想方案：雲端宏觀解析】...
2025-10-07 22:51:18 - [ERROR] - [512280345618546699] [LORE 解析 1-1/3] 遭遇未知錯誤: 格式化 Prompt 失敗：模板中需要的鍵 ['player_location', 'viewing_mode', 'player_location', 'remote_target_path_str', 'remote_target_path_str'] 在提供的參數中缺失。，正在降級。
2025-10-07 22:51:18 - [INFO] - [512280345618546699] [LORE 解析 1-2/3] 正在嘗試【本地備援方案：無審查解析】...
2025-10-07 22:51:18 - [INFO] - [512280345618546699] 正在使用本地模型 'HammerAI/llama-3-lexi-uncensored:latest' 進行LORE解析 (Attempt 1/2)...
2025-10-07 22:57:55 - [INFO] - 正在加載核心 Cog (core_cog)...
2025-10-07 22:58:01 - [INFO] - ✅ 核心 Cog (core_cog) 已加載，並且所有持久化視圖已成功註冊。
2025-10-07 22:58:01 - [INFO] - ✅ 核心 Cog 加載成功。
2025-10-07 22:58:01 - [INFO] - 正在全域同步應用程式指令...
2025-10-07 22:58:01 - [INFO] - ✅ 指令已全域同步！
2025-10-07 22:58:01 - [INFO] - Discord Bot setup hook finished!
2025-10-07 22:58:04 - [INFO] - Logged in as AI#4450 (ID: 1358417100250808531)
2025-10-07 22:58:05 - [INFO] - 已成功發送啟動成功通知給管理員。
2025-10-07 22:58:13 - [INFO] - [512280345618546699] [Data Reset] 正在啟動使用者資料重置流程...
2025-10-07 22:58:14 - [INFO] - [512280345618546699] [Data Reset] 所有相關的資料庫記錄已成功刪除。
2025-10-07 22:58:14 - [INFO] - [512280345618546699] [Data Reset] 向量儲存目錄 'D:\DINO\SD\ComfyUI\personal_server\ai_lover_service\data\vector_stores\512280345618546699' 已成功刪除。
2025-10-07 22:58:14 - [INFO] - [512280345618546699] [Data Reset] 資料重置流程已全部完成。
2025-10-07 22:58:16 - [INFO] - [512280345618546699] (UI Event) Persistent 'StartSetupView' button clicked.
2025-10-07 22:58:20 - [INFO] - 使用者 512280345618546699 沒有活躍的 AI 實例，嘗試創建...
2025-10-07 22:58:20 - [INFO] - [512280345618546699] 處於設定流程中，即使資料庫無記錄，也創建一個臨時的記憶體實例。
2025-10-07 22:58:20 - [INFO] - [512280345618546699] 核心數據模板 'world_snapshot_template.txt' 已成功加載。
2025-10-07 22:58:20 - [INFO] - [512280345618546699] 核心協議 '00_supreme_directive.txt' 已成功加載。
2025-10-07 22:58:20 - [INFO] - ✅ [Embedding Loader] 檢測到本地模型路徑，正在嘗試從 'D:\DINO\SD\ComfyUI\personal_server\ai_lover_service\models\stella-base-zh-v2' 加載...
2025-10-07 22:58:29 - [INFO] - ✅ [Embedding Loader] 本地 Embedding 模型實例創建成功。
2025-10-07 22:58:29 - [INFO] - [512280345618546699] 所有輕量級前置資源已準備就緒 (RAG 創建已延遲)。
2025-10-07 22:58:29 - [INFO] - [512280345618546699] 接收到 profile 更新請求: ['world_settings']
2025-10-07 22:58:29 - [WARNING] - [512280345618546699] 在持久化更新時找不到使用者資料，將創建新記錄。
2025-10-07 22:58:29 - [INFO] - [512280345618546699] Profile 更新並持久化成功。
2025-10-07 22:58:31 - [INFO] - [512280345618546699] (UI Event) Persistent 'ContinueToUserSetupView' button clicked.
2025-10-07 22:58:38 - [INFO] - [512280345618546699] (UI Event) CharacterSettingsModal submitted for profile_type: 'user', is_setup_flow: True
2025-10-07 22:58:39 - [INFO] - [512280345618546699] 接收到 profile 更新請求: ['user_profile']
2025-10-07 22:58:39 - [INFO] - [512280345618546699] Profile 更新並持久化成功。
2025-10-07 22:58:40 - [INFO] - [512280345618546699] (UI Event) Persistent 'ContinueToAiSetupView' button clicked.
2025-10-07 22:58:51 - [INFO] - [512280345618546699] (UI Event) CharacterSettingsModal submitted for profile_type: 'ai', is_setup_flow: True
2025-10-07 22:58:52 - [INFO] - [512280345618546699] 接收到 profile 更新請求: ['ai_profile']
2025-10-07 22:58:52 - [INFO] - [512280345618546699] Profile 更新並持久化成功。
2025-10-07 22:58:53 - [INFO] - [512280345618546699] [創世流程] 檔案上傳開始，已設定 active_setups 狀態鎖。
2025-10-07 22:58:59 - [INFO] - [512280345618546699] (on_message) 偵測到用戶處於活躍的創世流程中，已忽略常規訊息 '...' 以防止競爭。
2025-10-07 22:59:02 - [INFO] - [512280345618546699] [創世流程 v67.0] 原生 Python 驅動的流程已啟動。
2025-10-07 22:59:02 - [INFO] - [512280345618546699] [後台創世] 步驟 1/5: 正在解析世界聖經並創建 LORE 骨架...
2025-10-07 22:59:02 - [INFO] - [512280345618546699] [數據入口-軌道B] 正在啟動 LORE 解析管線...
2025-10-07 22:59:02 - [INFO] - [512280345618546699] [LORE 解析] 已將世界聖經原文分割成 8 個文本塊進行處理。
2025-10-07 22:59:02 - [INFO] - [512280345618546699] [LORE 解析] 正在處理文本塊 1/8...
2025-10-07 22:59:02 - [INFO] - [512280345618546699] [LORE 解析 1-1/3] 正在嘗試【理想方案：雲端宏觀解析】...
2025-10-07 22:59:02 - [ERROR] - [512280345618546699] [LORE 解析 1-1/3] 遭遇未知錯誤: Replacement index 0 out of range for positional args tuple，正在降級。
2025-10-07 22:59:02 - [INFO] - [512280345618546699] [LORE 解析 1-2/3] 正在嘗試【本地備援方案：無審查解析】...
2025-10-07 22:59:02 - [INFO] - [512280345618546699] 正在使用本地模型 'HammerAI/llama-3-lexi-uncensored:latest' 進行LORE解析 (Attempt 1/2)...
2025-10-07 23:18:18 - [INFO] - 正在加載核心 Cog (core_cog)...
2025-10-07 23:18:24 - [INFO] - ✅ 核心 Cog (core_cog) 已加載，並且所有持久化視圖已成功註冊。
2025-10-07 23:18:24 - [INFO] - ✅ 核心 Cog 加載成功。
2025-10-07 23:18:24 - [INFO] - 正在全域同步應用程式指令...
2025-10-07 23:18:24 - [INFO] - ✅ 指令已全域同步！
2025-10-07 23:18:24 - [INFO] - Discord Bot setup hook finished!
2025-10-07 23:18:27 - [INFO] - Logged in as AI#4450 (ID: 1358417100250808531)
2025-10-07 23:18:27 - [INFO] - 已成功發送啟動成功通知給管理員。
2025-10-07 23:19:07 - [INFO] - [512280345618546699] [Data Reset] 正在啟動使用者資料重置流程...
2025-10-07 23:19:07 - [INFO] - [512280345618546699] [Data Reset] 所有相關的資料庫記錄已成功刪除。
2025-10-07 23:19:07 - [INFO] - [512280345618546699] [Data Reset] 向量儲存目錄 'D:\DINO\SD\ComfyUI\personal_server\ai_lover_service\data\vector_stores\512280345618546699' 已成功刪除。
2025-10-07 23:19:07 - [INFO] - [512280345618546699] [Data Reset] 資料重置流程已全部完成。
2025-10-07 23:19:22 - [INFO] - [512280345618546699] (UI Event) Persistent 'StartSetupView' button clicked.
2025-10-07 23:19:33 - [INFO] - 使用者 512280345618546699 沒有活躍的 AI 實例，嘗試創建...
2025-10-07 23:19:33 - [INFO] - [512280345618546699] 處於設定流程中，即使資料庫無記錄，也創建一個臨時的記憶體實例。
2025-10-07 23:19:33 - [INFO] - [512280345618546699] 核心數據模板 'world_snapshot_template.txt' 已成功加載。
2025-10-07 23:19:33 - [INFO] - [512280345618546699] 核心協議 '00_supreme_directive.txt' 已成功加載。
2025-10-07 23:19:33 - [INFO] - ✅ [Embedding Loader] 檢測到本地模型路徑，正在嘗試從 'D:\DINO\SD\ComfyUI\personal_server\ai_lover_service\models\stella-base-zh-v2' 加載...
2025-10-07 23:19:42 - [INFO] - ✅ [Embedding Loader] 本地 Embedding 模型實例創建成功。
2025-10-07 23:19:42 - [INFO] - [512280345618546699] 所有輕量級前置資源已準備就緒 (RAG 創建已延遲)。
2025-10-07 23:19:42 - [INFO] - [512280345618546699] 接收到 profile 更新請求: ['world_settings']
2025-10-07 23:19:42 - [WARNING] - [512280345618546699] 在持久化更新時找不到使用者資料，將創建新記錄。
2025-10-07 23:19:42 - [INFO] - [512280345618546699] Profile 更新並持久化成功。
2025-10-07 23:19:45 - [INFO] - [512280345618546699] (UI Event) Persistent 'ContinueToUserSetupView' button clicked.
2025-10-07 23:19:54 - [INFO] - [512280345618546699] (UI Event) CharacterSettingsModal submitted for profile_type: 'user', is_setup_flow: True
2025-10-07 23:19:55 - [INFO] - [512280345618546699] 接收到 profile 更新請求: ['user_profile']
2025-10-07 23:19:55 - [INFO] - [512280345618546699] Profile 更新並持久化成功。
2025-10-07 23:20:02 - [INFO] - [512280345618546699] (UI Event) Persistent 'ContinueToAiSetupView' button clicked.
2025-10-07 23:20:14 - [INFO] - [512280345618546699] (UI Event) CharacterSettingsModal submitted for profile_type: 'ai', is_setup_flow: True
2025-10-07 23:20:14 - [INFO] - [512280345618546699] 接收到 profile 更新請求: ['ai_profile']
2025-10-07 23:20:14 - [INFO] - [512280345618546699] Profile 更新並持久化成功。
2025-10-07 23:20:15 - [INFO] - [512280345618546699] [創世流程] 檔案上傳開始，已設定 active_setups 狀態鎖。
2025-10-07 23:20:21 - [INFO] - [512280345618546699] (on_message) 偵測到用戶處於活躍的創世流程中，已忽略常規訊息 '...' 以防止競爭。
2025-10-07 23:20:24 - [INFO] - [512280345618546699] [創世流程 v67.0] 原生 Python 驅動的流程已啟動。
2025-10-07 23:20:24 - [INFO] - [512280345618546699] [後台創世] 步驟 1/5: 正在解析世界聖經並創建 LORE 骨架...
2025-10-07 23:20:24 - [INFO] - [512280345618546699] [數據入口-軌道B] 正在啟動 LORE 解析管線...
2025-10-07 23:20:24 - [INFO] - [512280345618546699] [LORE 解析] 已將世界聖經原文分割成 8 個文本塊進行處理。
2025-10-07 23:20:24 - [INFO] - [512280345618546699] [LORE 解析] 正在處理文本塊 1/8...
2025-10-07 23:20:24 - [INFO] - [512280345618546699] [LORE 解析 1-1/3] 正在嘗試【理想方案：雲端宏觀解析】...
2025-10-07 23:20:39 - [INFO] - [512280345618546699] [LLM Success] Generation successful using model 'gemini-2.5-flash-lite' with API Key #0.
2025-10-07 23:20:39 - [INFO] - [512280345618546699] [LORE 解析 1-1/3] ✅ 成功！
2025-10-07 23:20:39 - [INFO] - [512280345618546699] [LORE 解析] 正在處理文本塊 2/8...
2025-10-07 23:20:39 - [INFO] - [512280345618546699] [LORE 解析 2-1/3] 正在嘗試【理想方案：雲端宏觀解析】...
2025-10-07 23:21:04 - [INFO] - [512280345618546699] [LLM Success] Generation successful using model 'gemini-2.5-flash-lite' with API Key #0.
2025-10-07 23:21:04 - [INFO] - [512280345618546699] [LORE 解析 2-1/3] ✅ 成功！
2025-10-07 23:21:04 - [INFO] - [512280345618546699] [LORE 解析] 正在處理文本塊 3/8...
2025-10-07 23:21:04 - [INFO] - [512280345618546699] [LORE 解析 3-1/3] 正在嘗試【理想方案：雲端宏觀解析】...
2025-10-07 23:21:22 - [INFO] - [512280345618546699] [LLM Success] Generation successful using model 'gemini-2.5-flash-lite' with API Key #0.
2025-10-07 23:21:22 - [INFO] - [512280345618546699] [LORE 解析 3-1/3] ✅ 成功！
2025-10-07 23:21:22 - [INFO] - [512280345618546699] [LORE 解析] 正在處理文本塊 4/8...
2025-10-07 23:21:22 - [INFO] - [512280345618546699] [LORE 解析 4-1/3] 正在嘗試【理想方案：雲端宏觀解析】...
2025-10-07 23:21:22 - [WARNING] - [512280345618546699] 模型 'gemini-2.5-flash-lite' (Key #0) 遭遇內容審查或安全錯誤: BlockedPromptException。
2025-10-07 23:21:22 - [WARNING] - [512280345618546699] [LORE 解析 4-1/3] 遭遇內容審查，正在降級...
2025-10-07 23:21:22 - [INFO] - [512280345618546699] [LORE 解析 4-2/3] 正在嘗試【本地備援方案：無審查解析】...
2025-10-07 23:21:22 - [INFO] - [512280345618546699] 正在使用本地模型 'HammerAI/llama-3-lexi-uncensored:latest' 進行LORE解析 (Attempt 1/2)...
2025-10-07 23:26:23 - [ERROR] - [512280345618546699] 呼叫本地 Ollama 模型時發生未知錯誤: 
Traceback (most recent call last):
  File "C:\Users\USER\AppData\Local\Programs\Python\Python310\lib\site-packages\httpx\_transports\default.py", line 69, in map_httpcore_exceptions
    yield
  File "C:\Users\USER\AppData\Local\Programs\Python\Python310\lib\site-packages\httpx\_transports\default.py", line 373, in handle_async_request
    resp = await self._pool.handle_async_request(req)
  File "C:\Users\USER\AppData\Local\Programs\Python\Python310\lib\site-packages\httpcore\_async\connection_pool.py", line 256, in handle_async_request
    raise exc from None
  File "C:\Users\USER\AppData\Local\Programs\Python\Python310\lib\site-packages\httpcore\_async\connection_pool.py", line 236, in handle_async_request
    response = await connection.handle_async_request(
  File "C:\Users\USER\AppData\Local\Programs\Python\Python310\lib\site-packages\httpcore\_async\connection.py", line 103, in handle_async_request
    return await self._connection.handle_async_request(request)
  File "C:\Users\USER\AppData\Local\Programs\Python\Python310\lib\site-packages\httpcore\_async\http11.py", line 136, in handle_async_request
    raise exc
  File "C:\Users\USER\AppData\Local\Programs\Python\Python310\lib\site-packages\httpcore\_async\http11.py", line 106, in handle_async_request
    ) = await self._receive_response_headers(**kwargs)
  File "C:\Users\USER\AppData\Local\Programs\Python\Python310\lib\site-packages\httpcore\_async\http11.py", line 177, in _receive_response_headers
    event = await self._receive_event(timeout=timeout)
  File "C:\Users\USER\AppData\Local\Programs\Python\Python310\lib\site-packages\httpcore\_async\http11.py", line 217, in _receive_event
    data = await self._network_stream.read(
  File "C:\Users\USER\AppData\Local\Programs\Python\Python310\lib\site-packages\httpcore\_backends\anyio.py", line 32, in read
    with map_exceptions(exc_map):
  File "C:\Users\USER\AppData\Local\Programs\Python\Python310\lib\contextlib.py", line 153, in __exit__
    self.gen.throw(typ, value, traceback)
  File "C:\Users\USER\AppData\Local\Programs\Python\Python310\lib\site-packages\httpcore\_exceptions.py", line 14, in map_exceptions
    raise to_exc(exc) from exc
httpcore.ReadTimeout

The above exception was the direct cause of the following exception:

Traceback (most recent call last):
  File "D:\DINO\SD\ComfyUI\personal_server\ai_lover_service\src\ai_core.py", line 2059, in _invoke_local_ollama_parser
    response = await client.post("http://localhost:11434/api/generate", json=payload)
  File "C:\Users\USER\AppData\Local\Programs\Python\Python310\lib\site-packages\httpx\_client.py", line 1892, in post
    return await self.request(
  File "C:\Users\USER\AppData\Local\Programs\Python\Python310\lib\site-packages\httpx\_client.py", line 1574, in request
    return await self.send(request, auth=auth, follow_redirects=follow_redirects)
  File "C:\Users\USER\AppData\Local\Programs\Python\Python310\lib\site-packages\httpx\_client.py", line 1661, in send
    response = await self._send_handling_auth(
  File "C:\Users\USER\AppData\Local\Programs\Python\Python310\lib\site-packages\httpx\_client.py", line 1689, in _send_handling_auth
    response = await self._send_handling_redirects(
  File "C:\Users\USER\AppData\Local\Programs\Python\Python310\lib\site-packages\httpx\_client.py", line 1726, in _send_handling_redirects
    response = await self._send_single_request(request)
  File "C:\Users\USER\AppData\Local\Programs\Python\Python310\lib\site-packages\httpx\_client.py", line 1763, in _send_single_request
    response = await transport.handle_async_request(request)
  File "C:\Users\USER\AppData\Local\Programs\Python\Python310\lib\site-packages\httpx\_transports\default.py", line 372, in handle_async_request
    with map_httpcore_exceptions():
  File "C:\Users\USER\AppData\Local\Programs\Python\Python310\lib\contextlib.py", line 153, in __exit__
    self.gen.throw(typ, value, traceback)
  File "C:\Users\USER\AppData\Local\Programs\Python\Python310\lib\site-packages\httpx\_transports\default.py", line 86, in map_httpcore_exceptions
    raise mapped_exc(message) from exc
httpx.ReadTimeout
2025-10-07 23:26:23 - [WARNING] - [512280345618546699] [LORE 解析 4-2/3] 本地模型未能成功解析或返回空結果，正在降級...
2025-10-07 23:26:23 - [INFO] - [512280345618546699] [LORE 解析 4-3/3] 正在嘗試【法醫級重構方案】...
2025-10-07 23:26:28 - [INFO] - [512280345618546699] [LLM Success] Generation successful using model 'gemini-2.5-flash-lite' with API Key #0.
2025-10-07 23:26:28 - [INFO] - [512280345618546699] [LORE 解析 4-3/3] ✅ 成功！
2025-10-07 23:26:28 - [INFO] - [512280345618546699] [LORE 解析] 正在處理文本塊 5/8...
2025-10-07 23:26:28 - [INFO] - [512280345618546699] [LORE 解析 5-1/3] 正在嘗試【理想方案：雲端宏觀解析】...
2025-10-07 23:26:28 - [WARNING] - [512280345618546699] 模型 'gemini-2.5-flash-lite' (Key #0) 遭遇內容審查或安全錯誤: BlockedPromptException。
2025-10-07 23:26:28 - [WARNING] - [512280345618546699] [LORE 解析 5-1/3] 遭遇內容審查，正在降級...
2025-10-07 23:26:28 - [INFO] - [512280345618546699] [LORE 解析 5-2/3] 正在嘗試【本地備援方案：無審查解析】...
2025-10-07 23:26:28 - [INFO] - [512280345618546699] 正在使用本地模型 'HammerAI/llama-3-lexi-uncensored:latest' 進行LORE解析 (Attempt 1/2)...
2025-10-07 23:33:06 - [INFO] - 正在加載核心 Cog (core_cog)...
2025-10-07 23:33:11 - [INFO] - ✅ 核心 Cog (core_cog) 已加載，並且所有持久化視圖已成功註冊。
2025-10-07 23:33:11 - [INFO] - ✅ 核心 Cog 加載成功。
2025-10-07 23:33:11 - [INFO] - 正在全域同步應用程式指令...
2025-10-07 23:33:11 - [INFO] - ✅ 指令已全域同步！
2025-10-07 23:33:11 - [INFO] - Discord Bot setup hook finished!
2025-10-07 23:33:14 - [INFO] - Logged in as AI#4450 (ID: 1358417100250808531)
2025-10-07 23:33:14 - [INFO] - 已成功發送啟動成功通知給管理員。
2025-10-07 23:33:55 - [INFO] - [512280345618546699] [Data Reset] 正在啟動使用者資料重置流程...
2025-10-07 23:33:55 - [INFO] - [512280345618546699] [Data Reset] 所有相關的資料庫記錄已成功刪除。
2025-10-07 23:33:55 - [INFO] - [512280345618546699] [Data Reset] 向量儲存目錄 'D:\DINO\SD\ComfyUI\personal_server\ai_lover_service\data\vector_stores\512280345618546699' 已成功刪除。
2025-10-07 23:33:55 - [INFO] - [512280345618546699] [Data Reset] 資料重置流程已全部完成。
2025-10-07 23:33:57 - [INFO] - [512280345618546699] (UI Event) Persistent 'StartSetupView' button clicked.
2025-10-07 23:34:01 - [INFO] - 使用者 512280345618546699 沒有活躍的 AI 實例，嘗試創建...
2025-10-07 23:34:01 - [INFO] - [512280345618546699] 處於設定流程中，即使資料庫無記錄，也創建一個臨時的記憶體實例。
2025-10-07 23:34:01 - [INFO] - [512280345618546699] 核心數據模板 'world_snapshot_template.txt' 已成功加載。
2025-10-07 23:34:01 - [INFO] - [512280345618546699] 核心協議 '00_supreme_directive.txt' 已成功加載。
2025-10-07 23:34:01 - [INFO] - ✅ [Embedding Loader] 檢測到本地模型路徑，正在嘗試從 'D:\DINO\SD\ComfyUI\personal_server\ai_lover_service\models\stella-base-zh-v2' 加載...
2025-10-07 23:34:09 - [INFO] - ✅ [Embedding Loader] 本地 Embedding 模型實例創建成功。
2025-10-07 23:34:09 - [INFO] - [512280345618546699] 所有輕量級前置資源已準備就緒 (RAG 創建已延遲)。
2025-10-07 23:34:09 - [INFO] - [512280345618546699] 接收到 profile 更新請求: ['world_settings']
2025-10-07 23:34:09 - [WARNING] - [512280345618546699] 在持久化更新時找不到使用者資料，將創建新記錄。
2025-10-07 23:34:09 - [INFO] - [512280345618546699] Profile 更新並持久化成功。
2025-10-07 23:34:14 - [INFO] - [512280345618546699] (UI Event) Persistent 'ContinueToUserSetupView' button clicked.
2025-10-07 23:34:30 - [INFO] - [512280345618546699] (UI Event) CharacterSettingsModal submitted for profile_type: 'user', is_setup_flow: True
2025-10-07 23:34:30 - [INFO] - [512280345618546699] 接收到 profile 更新請求: ['user_profile']
2025-10-07 23:34:30 - [INFO] - [512280345618546699] Profile 更新並持久化成功。
2025-10-07 23:34:54 - [INFO] - [512280345618546699] (UI Event) Persistent 'ContinueToAiSetupView' button clicked.
2025-10-07 23:35:06 - [INFO] - [512280345618546699] (UI Event) CharacterSettingsModal submitted for profile_type: 'ai', is_setup_flow: True
2025-10-07 23:35:06 - [INFO] - [512280345618546699] 接收到 profile 更新請求: ['ai_profile']
2025-10-07 23:35:07 - [INFO] - [512280345618546699] Profile 更新並持久化成功。
2025-10-07 23:35:08 - [INFO] - [512280345618546699] [創世流程] 檔案上傳開始，已設定 active_setups 狀態鎖。
2025-10-07 23:35:14 - [INFO] - [512280345618546699] (on_message) 偵測到用戶處於活躍的創世流程中，已忽略常規訊息 '...' 以防止競爭。
2025-10-07 23:35:17 - [INFO] - [512280345618546699] [創世流程 v67.0] 原生 Python 驅動的流程已啟動。
2025-10-07 23:35:17 - [INFO] - [512280345618546699] [後台創世] 步驟 1/5: 正在解析世界聖經並創建 LORE 骨架...
2025-10-07 23:35:17 - [INFO] - [512280345618546699] [數據入口-軌道B] 正在啟動 LORE 解析管線...
2025-10-07 23:35:17 - [INFO] - [512280345618546699] [LORE 解析] 已將世界聖經原文分割成 8 個文本塊進行處理。
2025-10-07 23:35:17 - [INFO] - [512280345618546699] [LORE 解析] 正在處理文本塊 1/8...
2025-10-07 23:35:17 - [INFO] - [512280345618546699] [LORE 解析 1-1/3] 正在嘗試【理想方案：雲端宏觀解析】...
2025-10-07 23:35:30 - [INFO] - [512280345618546699] [LLM Success] Generation successful using model 'gemini-2.5-flash-lite' with API Key #0.
2025-10-07 23:35:30 - [INFO] - [512280345618546699] [LORE 解析 1-1/3] ✅ 成功！
2025-10-07 23:35:30 - [INFO] - [512280345618546699] [LORE 解析] 正在處理文本塊 2/8...
2025-10-07 23:35:30 - [INFO] - [512280345618546699] [LORE 解析 2-1/3] 正在嘗試【理想方案：雲端宏觀解析】...
2025-10-07 23:35:50 - [INFO] - [512280345618546699] [LLM Success] Generation successful using model 'gemini-2.5-flash-lite' with API Key #0.
2025-10-07 23:35:50 - [INFO] - [512280345618546699] [LORE 解析 2-1/3] ✅ 成功！
2025-10-07 23:35:50 - [INFO] - [512280345618546699] [LORE 解析] 正在處理文本塊 3/8...
2025-10-07 23:35:50 - [INFO] - [512280345618546699] [LORE 解析 3-1/3] 正在嘗試【理想方案：雲端宏觀解析】...
2025-10-07 23:36:05 - [INFO] - [512280345618546699] [LLM Success] Generation successful using model 'gemini-2.5-flash-lite' with API Key #0.
2025-10-07 23:36:05 - [INFO] - [512280345618546699] [LORE 解析 3-1/3] ✅ 成功！
2025-10-07 23:36:05 - [INFO] - [512280345618546699] [LORE 解析] 正在處理文本塊 4/8...
2025-10-07 23:36:05 - [INFO] - [512280345618546699] [LORE 解析 4-1/3] 正在嘗試【理想方案：雲端宏觀解析】...
2025-10-07 23:36:22 - [INFO] - [512280345618546699] [LLM Success] Generation successful using model 'gemini-2.5-flash-lite' with API Key #0.
2025-10-07 23:36:22 - [INFO] - [512280345618546699] [LORE 解析 4-1/3] ✅ 成功！
2025-10-07 23:36:22 - [INFO] - [512280345618546699] [LORE 解析] 正在處理文本塊 5/8...
2025-10-07 23:36:22 - [INFO] - [512280345618546699] [LORE 解析 5-1/3] 正在嘗試【理想方案：雲端宏觀解析】...
2025-10-07 23:36:23 - [WARNING] - [512280345618546699] 模型 'gemini-2.5-flash-lite' (Key #0) 遭遇內容審查或安全錯誤: BlockedPromptException。
2025-10-07 23:36:23 - [WARNING] - [512280345618546699] [LORE 解析 5-1/3] 遭遇內容審查，正在降級...
2025-10-07 23:36:23 - [INFO] - [512280345618546699] [LORE 解析 5-2/3] 正在嘗試【本地備援方案：無審查解析】...
2025-10-07 23:36:23 - [INFO] - [512280345618546699] 正在使用本地模型 'HammerAI/llama-3-lexi-uncensored:latest' 進行LORE解析 (Attempt 1/2)...
