### AI Lover Log - Last updated at 2025-09-11T21:25:14.803335 ###

2025-09-11 21:05:58 - [INFO] - [512280345618546699] 對話記錄已成功保存到 SQL 資料庫。
2025-09-11 21:05:58 - [ERROR] - [512280345618546699] 將互動保存到資料庫時發生錯誤: Error embedding content: 429 You exceeded your current quota, please check your plan and billing details. For more information on this error, head to: https://ai.google.dev/gemini-api/docs/rate-limits. [violations {
  quota_metric: "generativelanguage.googleapis.com/embed_content_free_tier_requests"
  quota_id: "EmbedContentRequestsPerDayPerUserPerProjectPerModel-FreeTier"
}
violations {
  quota_metric: "generativelanguage.googleapis.com/embed_content_free_tier_requests"
  quota_id: "EmbedContentRequestsPerMinutePerUserPerProjectPerModel-FreeTier"
}
violations {
  quota_metric: "generativelanguage.googleapis.com/embed_content_free_tier_requests"
  quota_id: "EmbedContentRequestsPerMinutePerProjectPerModel-FreeTier"
}
violations {
  quota_metric: "generativelanguage.googleapis.com/embed_content_free_tier_requests"
  quota_id: "EmbedContentRequestsPerDayPerProjectPerModel-FreeTier"
}
, links {
  description: "Learn more about Gemini API quotas"
  url: "https://ai.google.dev/gemini-api/docs/rate-limits"
}
]
Traceback (most recent call last):
  File "C:\Users\USER\AppData\Local\Programs\Python\Python310\lib\site-packages\langchain_google_genai\embeddings.py", line 227, in embed_documents
    result = self.client.batch_embed_contents(
  File "C:\Users\USER\AppData\Local\Programs\Python\Python310\lib\site-packages\google\ai\generativelanguage_v1beta\services\generative_service\client.py", line 1392, in batch_embed_contents
    response = rpc(
  File "C:\Users\USER\AppData\Local\Programs\Python\Python310\lib\site-packages\google\api_core\gapic_v1\method.py", line 131, in __call__
    return wrapped_func(*args, **kwargs)
  File "C:\Users\USER\AppData\Local\Programs\Python\Python310\lib\site-packages\google\api_core\retry\retry_unary.py", line 294, in retry_wrapped_func
    return retry_target(
  File "C:\Users\USER\AppData\Local\Programs\Python\Python310\lib\site-packages\google\api_core\retry\retry_unary.py", line 156, in retry_target
    next_sleep = _retry_error_helper(
  File "C:\Users\USER\AppData\Local\Programs\Python\Python310\lib\site-packages\google\api_core\retry\retry_base.py", line 214, in _retry_error_helper
    raise final_exc from source_exc
  File "C:\Users\USER\AppData\Local\Programs\Python\Python310\lib\site-packages\google\api_core\retry\retry_unary.py", line 147, in retry_target
    result = target()
  File "C:\Users\USER\AppData\Local\Programs\Python\Python310\lib\site-packages\google\api_core\timeout.py", line 130, in func_with_timeout
    return func(*args, **kwargs)
  File "C:\Users\USER\AppData\Local\Programs\Python\Python310\lib\site-packages\google\api_core\grpc_helpers.py", line 78, in error_remapped_callable
    raise exceptions.from_grpc_error(exc) from exc
google.api_core.exceptions.ResourceExhausted: 429 You exceeded your current quota, please check your plan and billing details. For more information on this error, head to: https://ai.google.dev/gemini-api/docs/rate-limits. [violations {
  quota_metric: "generativelanguage.googleapis.com/embed_content_free_tier_requests"
  quota_id: "EmbedContentRequestsPerDayPerUserPerProjectPerModel-FreeTier"
}
violations {
  quota_metric: "generativelanguage.googleapis.com/embed_content_free_tier_requests"
  quota_id: "EmbedContentRequestsPerMinutePerUserPerProjectPerModel-FreeTier"
}
violations {
  quota_metric: "generativelanguage.googleapis.com/embed_content_free_tier_requests"
  quota_id: "EmbedContentRequestsPerMinutePerProjectPerModel-FreeTier"
}
violations {
  quota_metric: "generativelanguage.googleapis.com/embed_content_free_tier_requests"
  quota_id: "EmbedContentRequestsPerDayPerProjectPerModel-FreeTier"
}
, links {
  description: "Learn more about Gemini API quotas"
  url: "https://ai.google.dev/gemini-api/docs/rate-limits"
}
]

The above exception was the direct cause of the following exception:

Traceback (most recent call last):
  File "D:\DINO\SD\ComfyUI\personal_server\ai_lover_service\src\ai_core.py", line 3030, in _save_interaction_to_dbs
    await asyncio.to_thread(
  File "C:\Users\USER\AppData\Local\Programs\Python\Python310\lib\asyncio\threads.py", line 25, in to_thread
    return await loop.run_in_executor(None, func_call)
  File "C:\Users\USER\AppData\Local\Programs\Python\Python310\lib\concurrent\futures\thread.py", line 58, in run
    result = self.fn(*self.args, **self.kwargs)
  File "C:\Users\USER\AppData\Local\Programs\Python\Python310\lib\site-packages\langchain_chroma\vectorstores.py", line 606, in add_texts
    embeddings = self._embedding_function.embed_documents(texts)
  File "C:\Users\USER\AppData\Local\Programs\Python\Python310\lib\site-packages\langchain_google_genai\embeddings.py", line 231, in embed_documents
    raise GoogleGenerativeAIError(f"Error embedding content: {e}") from e
langchain_google_genai._common.GoogleGenerativeAIError: Error embedding content: 429 You exceeded your current quota, please check your plan and billing details. For more information on this error, head to: https://ai.google.dev/gemini-api/docs/rate-limits. [violations {
  quota_metric: "generativelanguage.googleapis.com/embed_content_free_tier_requests"
  quota_id: "EmbedContentRequestsPerDayPerUserPerProjectPerModel-FreeTier"
}
violations {
  quota_metric: "generativelanguage.googleapis.com/embed_content_free_tier_requests"
  quota_id: "EmbedContentRequestsPerMinutePerUserPerProjectPerModel-FreeTier"
}
violations {
  quota_metric: "generativelanguage.googleapis.com/embed_content_free_tier_requests"
  quota_id: "EmbedContentRequestsPerMinutePerProjectPerModel-FreeTier"
}
violations {
  quota_metric: "generativelanguage.googleapis.com/embed_content_free_tier_requests"
  quota_id: "EmbedContentRequestsPerDayPerProjectPerModel-FreeTier"
}
, links {
  description: "Learn more about Gemini API quotas"
  url: "https://ai.google.dev/gemini-api/docs/rate-limits"
}
]
2025-09-11 21:06:02 - [INFO] - [512280345618546699] 任務成功: 已成功為新物種 '碧' 創建了百科詞條。
2025-09-11 21:06:02 - [INFO] - --- [512280345618546699] 場景擴展計畫執行完畢 ---
2025-09-11 21:06:02 - [INFO] - [512280345618546699] 背景任務的工具上下文已清理。
