### AI Lover Log - Last updated at 2025-09-13T01:05:28.228653 ###

    return await failed_chain.ainvoke(retry_params)
  File "C:\Users\USER\AppData\Local\Programs\Python\Python310\lib\site-packages\langchain_core\runnables\base.py", line 3088, in ainvoke
    input_ = await coro_with_context(part(), context, create_task=True)
  File "C:\Users\USER\AppData\Local\Programs\Python\Python310\lib\site-packages\langchain_core\prompts\base.py", line 242, in ainvoke
    return await self._acall_with_config(
  File "C:\Users\USER\AppData\Local\Programs\Python\Python310\lib\site-packages\langchain_core\runnables\base.py", line 1990, in _acall_with_config
    output: Output = await coro_with_context(coro, context)
  File "C:\Users\USER\AppData\Local\Programs\Python\Python310\lib\site-packages\langchain_core\prompts\base.py", line 195, in _aformat_prompt_with_error_handling
    inner_input_ = self._validate_input(inner_input)
  File "C:\Users\USER\AppData\Local\Programs\Python\Python310\lib\site-packages\langchain_core\prompts\base.py", line 183, in _validate_input
    raise KeyError(
KeyError: "Input to ChatPromptTemplate is missing variables {'ai_name', 'username'}.  Expected: ['ai_name', 'existing_lore_summary', 'final_response_text', 'user_input', 'username'] Received: ['existing_lore_summary', 'user_input', 'final_response_text']\nNote: if you intended {ai_name} to be part of the string and not a variable, please escape it with double curly braces like: '{{ai_name}}'.\nFor troubleshooting, visit: https://python.langchain.com/docs/troubleshooting/errors/INVALID_PROMPT_INPUT "
2025-09-13 00:40:40 - [WARNING] - [512280345618546699] 背景LORE提取鏈的LLM回應為空或最終失敗，已跳過本輪LORE擴展。
2025-09-13 00:50:07 - [INFO] - 所有持久化 UI 視圖已成功註冊。
2025-09-13 00:50:07 - [INFO] - Discord Bot is ready and commands are synced!
2025-09-13 00:50:10 - [INFO] - 【健康檢查 & Keep-Alive】背景任務已啟動。
2025-09-13 00:50:10 - [INFO] - Logged in as AI#4450 (ID: 1358417100250808531)
2025-09-13 00:50:10 - [INFO] - 已成功發送啟動成功通知給管理員。
2025-09-13 00:56:11 - [INFO] - 使用者 512280345618546699 沒有活躍的 AI 實例，嘗試創建...
2025-09-13 00:56:11 - [INFO] - [512280345618546699] 核心數據模板 'world_snapshot_template.txt' 已成功加載。
2025-09-13 00:56:11 - [INFO] - [512280345618546699] 核心協議模板 '00_supreme_directive.txt' 已成功加載並設置。
2025-09-13 00:56:11 - [INFO] - [512280345618546699] 已精簡模組化提示詞加載，只保留核心協議。
2025-09-13 00:56:11 - [INFO] - [512280345618546699] 正在創建模型 'gemini-2.5-flash-lite' 實例 (API Key index: 0)
2025-09-13 00:56:11 - [INFO] - [512280345618546699] (Retriever Builder) 已從 SQL 加載 2 條記憶。
2025-09-13 00:56:11 - [INFO] - [512280345618546699] (Retriever Builder) BM25 備援檢索器構建成功。
2025-09-13 00:56:11 - [INFO] - [512280345618546699] 正在創建 Embedding 模型實例 (API Key index: 1)
2025-09-13 00:56:13 - [INFO] - [512280345618546699] (Retriever Builder) ChromaDB 主要檢索器構建成功。
2025-09-13 00:56:13 - [INFO] - [512280345618546699] (Retriever Builder) 混合檢索器構建成功。
2025-09-13 00:56:13 - [INFO] - [512280345618546699] 所有構建鏈的前置資源已準備就緒。
2025-09-13 00:56:13 - [INFO] - [512280345618546699] 正在從資料庫恢復短期記憶...
2025-09-13 00:56:13 - [INFO] - [512280345618546699] 成功恢復了 2 條對話記錄到短期記憶中。
2025-09-13 00:56:13 - [INFO] - 為使用者 512280345618546699 成功創建並初始化 AI 實例。
2025-09-13 00:56:13 - [INFO] - [512280345618546699] 响应条件满足，启动 LangGraph 對話流程...
2025-09-13 00:56:14 - [INFO] - [512280345618546699] (Graph|1) Node: perceive_scene -> 正在感知场景...
2025-09-13 00:56:14 - [INFO] - [512280345618546699] 正在創建模型 'gemini-2.5-flash-lite' 實例 (API Key index: 2)
2025-09-13 00:56:14 - [INFO] - [512280345618546699] --- 開始嘗試模型: 'gemini-2.5-flash-lite' (優先級 1/1) ---
2025-09-13 00:56:14 - [INFO] - [512280345618546699] 正在創建模型 'gemini-2.5-flash-lite' 實例 (API Key index: 3)
2025-09-13 00:56:15 - [INFO] - [512280345618546699] 導演視角模式已從 'remote' (路徑: ['性神城的街道']) 更新為 'remote' (路徑: ['神城的街道'])
2025-09-13 00:56:15 - [INFO] - [512280345618546699] 接收到 profile 更新請求: ['game_state']
2025-09-13 00:56:15 - [INFO] - [512280345618546699] Profile 更新並持久化成功。
2025-09-13 00:56:15 - [INFO] - [512280345618546699] (Graph|1) 场景感知完成。最终视角: 'remote'
2025-09-13 00:56:15 - [INFO] - [512280345618546699] (Graph|2) Node: retrieve_and_query -> 正在檢索記憶與查詢LORE...
2025-09-13 00:56:15 - [INFO] - [512280345618546699] 正在創建模型 'gemini-2.5-flash-lite' 實例 (API Key index: 4)
2025-09-13 00:56:15 - [INFO] - [512280345618546699] --- 開始嘗試模型: 'gemini-2.5-flash-lite' (優先級 1/1) ---
2025-09-13 00:56:15 - [INFO] - [512280345618546699] 正在創建模型 'gemini-2.5-flash-lite' 實例 (API Key index: 5)
2025-09-13 00:56:17 - [INFO] - [512280345618546699] (Graph|2) 輸入較複雜，執行 RAG 檢索...
2025-09-13 00:56:17 - [INFO] - [512280345618546699] (RAG Executor) [主方案] 正在使用主記憶系統 (Embedding + BM25) 進行檢索...
2025-09-13 00:56:18 - [WARNING] - [512280345618546699] (RAG Executor) [主方案失敗] 主記憶系統 (Embedding) 因達到 API 配額限制而失敗。錯誤: GoogleGenerativeAIError
2025-09-13 00:56:18 - [INFO] - [512280345618546699] (RAG Executor) [備援觸發] 正在啟動備援記憶系統 (BM25)...
2025-09-13 00:56:18 - [INFO] - [512280345618546699] (RAG Executor) [備援成功] 備援記憶系統 (BM25) 檢索成功。
2025-09-13 00:56:18 - [INFO] - [512280345618546699] (Batch Sanitizer) 檢索到 2 份文檔，正在進行批次清洗與摘要...
2025-09-13 00:56:18 - [INFO] - [512280345618546699] --- 開始嘗試模型: 'gemini-2.5-flash-lite' (優先級 1/1) ---
2025-09-13 00:56:18 - [INFO] - [512280345618546699] 正在創建模型 'gemini-2.5-flash-lite' 實例 (API Key index: 0)
2025-09-13 00:56:20 - [INFO] - [512280345618546699] (Batch Sanitizer) 批次清洗成功，正在基於安全的文學概述進行最終摘要...
2025-09-13 00:56:20 - [INFO] - [512280345618546699] 正在創建模型 'gemini-2.5-flash-lite' 實例 (API Key index: 1)
2025-09-13 00:56:20 - [INFO] - [512280345618546699] --- 開始嘗試模型: 'gemini-2.5-flash-lite' (優先級 1/1) ---
2025-09-13 00:56:20 - [INFO] - [512280345618546699] 正在創建模型 'gemini-2.5-flash-lite' 實例 (API Key index: 2)
2025-09-13 00:56:21 - [INFO] - [512280345618546699] 已成功將 RAG 上下文提煉為事實要點。
2025-09-13 00:56:21 - [INFO] - [512280345618546699] 正在創建模型 'gemini-2.5-flash-lite' 實例 (API Key index: 3)
2025-09-13 00:56:21 - [INFO] - [512280345618546699] --- 開始嘗試模型: 'gemini-2.5-flash-lite' (優先級 1/1) ---
2025-09-13 00:56:21 - [INFO] - [512280345618546699] 正在創建模型 'gemini-2.5-flash-lite' 實例 (API Key index: 4)
2025-09-13 00:56:22 - [INFO] - [512280345618546699] (LORE Querier) 查詢完成，共找到 0 條唯一的 LORE 記錄。
2025-09-13 00:56:22 - [INFO] - [512280345618546699] (Graph|2) 查詢完成。檢索到 0 條相關LORE。
2025-09-13 00:56:22 - [INFO] - [512280345618546699] (Graph|3) Node: expansion_decision_and_execution -> 正在決策是否擴展LORE...
2025-09-13 00:56:22 - [INFO] - [512280345618546699] 正在創建模型 'gemini-2.5-flash-lite' 實例 (API Key index: 5)
2025-09-13 00:56:22 - [INFO] - [512280345618546699] --- 開始嘗試模型: 'gemini-2.5-flash-lite' (優先級 1/1) ---
2025-09-13 00:56:22 - [INFO] - [512280345618546699] 正在創建模型 'gemini-2.5-flash-lite' 實例 (API Key index: 0)
2025-09-13 00:56:23 - [INFO] - [512280345618546699] (Graph|3) 決策結果：需要擴展。理由: 劇本引入了新的第三方角色「性神教徒」和「乞丐」，且現有名單中沒有合適的角色，因此需要擴展。。正在執行LORE擴展...
2025-09-13 00:56:23 - [INFO] - [512280345618546699] (Graph|3) 擴展 Plan A: 嘗試使用主選角鏈...
2025-09-13 00:56:23 - [INFO] - [512280345618546699] 正在創建模型 'gemini-2.5-flash-lite' 實例 (API Key index: 1)
2025-09-13 00:56:23 - [WARNING] - [512280345618546699] (Graph|3) 擴展 Plan A 失敗: 'AILover' object has no attribute 'get_character_quantification_chain'。啟動【Gemini子任務鏈備援】...
2025-09-13 00:56:23 - [INFO] - [512280345618546699] (Fallback) 正在启动 Gemini 子任务链 LORE 扩展备援...
2025-09-13 00:56:23 - [ERROR] - 處理使用者 512280345618546699 的 LangGraph 聊天流程時發生異常: 'AILover' object has no attribute 'get_character_quantification_chain'
Traceback (most recent call last):
  File "D:\DINO\SD\ComfyUI\personal_server\ai_lover_service\src\graph.py", line 172, in expansion_decision_and_execution_node
    quant_chain = ai_core.get_character_quantification_chain()
AttributeError: 'AILover' object has no attribute 'get_character_quantification_chain'. Did you mean: 'character_quantification_chain'?

During handling of the above exception, another exception occurred:

Traceback (most recent call last):
  File "D:\DINO\SD\ComfyUI\personal_server\ai_lover_service\src\discord_bot.py", line 822, in on_message
    final_state = await self.main_response_graph.ainvoke(initial_state)
  File "C:\Users\USER\AppData\Local\Programs\Python\Python310\lib\site-packages\langgraph\pregel\main.py", line 3088, in ainvoke
    async for chunk in self.astream(
  File "C:\Users\USER\AppData\Local\Programs\Python\Python310\lib\site-packages\langgraph\pregel\main.py", line 2926, in astream
    async for _ in runner.atick(
  File "C:\Users\USER\AppData\Local\Programs\Python\Python310\lib\site-packages\langgraph\pregel\_runner.py", line 295, in atick
    await arun_with_retry(
  File "C:\Users\USER\AppData\Local\Programs\Python\Python310\lib\site-packages\langgraph\pregel\_retry.py", line 137, in arun_with_retry
    return await task.proc.ainvoke(task.input, config)
  File "C:\Users\USER\AppData\Local\Programs\Python\Python310\lib\site-packages\langgraph\_internal\_runnable.py", line 693, in ainvoke
    input = await step.ainvoke(input, config, **kwargs)
  File "C:\Users\USER\AppData\Local\Programs\Python\Python310\lib\site-packages\langgraph\_internal\_runnable.py", line 457, in ainvoke
    ret = await self.afunc(*args, **kwargs)
  File "D:\DINO\SD\ComfyUI\personal_server\ai_lover_service\src\graph.py", line 200, in expansion_decision_and_execution_node
    newly_created_lores = await ai_core.gemini_subtask_expansion_fallback(safe_query_text)
  File "D:\DINO\SD\ComfyUI\personal_server\ai_lover_service\src\ai_core.py", line 2299, in gemini_subtask_expansion_fallback
    quant_chain = self.get_character_quantification_chain()
AttributeError: 'AILover' object has no attribute 'get_character_quantification_chain'. Did you mean: 'character_quantification_chain'?
