### AI Lover Log - Last updated at 2025-09-09T18:43:54.391667 ###

  Field required [type=missing, input_value={'original_name': '性神...徒相關的場景。'}, input_type=dict]
    For further information visit https://errors.pydantic.dev/2.11/v/missing
standardized_name
  Field required [type=missing, input_value={'original_name': '性神...徒相關的場景。'}, input_type=dict]
    For further information visit https://errors.pydantic.dev/2.11/v/missing
Traceback (most recent call last):
  File "D:\DINO\SD\ComfyUI\personal_server\ai_lover_service\src\ai_core.py", line 3011, in _execute_tool_call_plan
    validated_retry_args = tool_to_execute.args_schema.model_validate(retry_params)
  File "C:\Users\USER\AppData\Local\Programs\Python\Python310\lib\site-packages\pydantic\main.py", line 705, in model_validate
    return cls.__pydantic_validator__.validate_python(
pydantic_core._pydantic_core.ValidationError: 2 validation errors for AddOrUpdateWorldLoreArgs
lore_key
  Field required [type=missing, input_value={'original_name': '性神...徒相關的場景。'}, input_type=dict]
    For further information visit https://errors.pydantic.dev/2.11/v/missing
standardized_name
  Field required [type=missing, input_value={'original_name': '性神...徒相關的場景。'}, input_type=dict]
    For further information visit https://errors.pydantic.dev/2.11/v/missing
2025-09-09 18:35:02 - [WARNING] - [512280345618546699] 工具 'add_or_update_world_lore' 首次執行失敗: 2 validation errors for AddOrUpdateWorldLoreArgs
lore_key
  Field required [type=missing, input_value={'original_name': '性神...對神祇的獻祭。'}, input_type=dict]
    For further information visit https://errors.pydantic.dev/2.11/v/missing
standardized_name
  Field required [type=missing, input_value={'original_name': '性神...對神祇的獻祭。'}, input_type=dict]
    For further information visit https://errors.pydantic.dev/2.11/v/missing。啟動【委婉化重試】策略...
2025-09-09 18:35:03 - [INFO] - [512280345618546699] (重試) 已生成安全參數 'content': '描述活物與神祇之間，與神恩澤相關的互動。'。正在用其重試工具 'add_or_update_world_lore'...
2025-09-09 18:35:03 - [ERROR] - [512280345618546699] 任務失敗 (重試後): for add_or_update_world_lore: 2 validation errors for AddOrUpdateWorldLoreArgs
lore_key
  Field required [type=missing, input_value={'original_name': '性神...澤相關的互動。'}, input_type=dict]
    For further information visit https://errors.pydantic.dev/2.11/v/missing
standardized_name
  Field required [type=missing, input_value={'original_name': '性神...澤相關的互動。'}, input_type=dict]
    For further information visit https://errors.pydantic.dev/2.11/v/missing
Traceback (most recent call last):
  File "D:\DINO\SD\ComfyUI\personal_server\ai_lover_service\src\ai_core.py", line 3011, in _execute_tool_call_plan
    validated_retry_args = tool_to_execute.args_schema.model_validate(retry_params)
  File "C:\Users\USER\AppData\Local\Programs\Python\Python310\lib\site-packages\pydantic\main.py", line 705, in model_validate
    return cls.__pydantic_validator__.validate_python(
pydantic_core._pydantic_core.ValidationError: 2 validation errors for AddOrUpdateWorldLoreArgs
lore_key
  Field required [type=missing, input_value={'original_name': '性神...澤相關的互動。'}, input_type=dict]
    For further information visit https://errors.pydantic.dev/2.11/v/missing
standardized_name
  Field required [type=missing, input_value={'original_name': '性神...澤相關的互動。'}, input_type=dict]
    For further information visit https://errors.pydantic.dev/2.11/v/missing
2025-09-09 18:35:07 - [WARNING] - [512280345618546699] 工具 'add_or_update_world_lore' 首次執行失敗: 2 validation errors for AddOrUpdateWorldLoreArgs
lore_key
  Field required [type=missing, input_value={'original_name': '塞巴...帶皮質手提包。'}, input_type=dict]
    For further information visit https://errors.pydantic.dev/2.11/v/missing
standardized_name
  Field required [type=missing, input_value={'original_name': '塞巴...帶皮質手提包。'}, input_type=dict]
    For further information visit https://errors.pydantic.dev/2.11/v/missing。啟動【委婉化重試】策略...
2025-09-09 18:35:08 - [INFO] - [512280345618546699] (重試) 已生成安全參數 'content': '塞巴斯蒂安與皮質手提包相關聯。'。正在用其重試工具 'add_or_update_world_lore'...
2025-09-09 18:35:08 - [ERROR] - [512280345618546699] 任務失敗 (重試後): for add_or_update_world_lore: 2 validation errors for AddOrUpdateWorldLoreArgs
lore_key
  Field required [type=missing, input_value={'original_name': '塞巴...手提包相關聯。'}, input_type=dict]
    For further information visit https://errors.pydantic.dev/2.11/v/missing
standardized_name
  Field required [type=missing, input_value={'original_name': '塞巴...手提包相關聯。'}, input_type=dict]
    For further information visit https://errors.pydantic.dev/2.11/v/missing
Traceback (most recent call last):
  File "D:\DINO\SD\ComfyUI\personal_server\ai_lover_service\src\ai_core.py", line 3011, in _execute_tool_call_plan
    validated_retry_args = tool_to_execute.args_schema.model_validate(retry_params)
  File "C:\Users\USER\AppData\Local\Programs\Python\Python310\lib\site-packages\pydantic\main.py", line 705, in model_validate
    return cls.__pydantic_validator__.validate_python(
pydantic_core._pydantic_core.ValidationError: 2 validation errors for AddOrUpdateWorldLoreArgs
lore_key
  Field required [type=missing, input_value={'original_name': '塞巴...手提包相關聯。'}, input_type=dict]
    For further information visit https://errors.pydantic.dev/2.11/v/missing
standardized_name
  Field required [type=missing, input_value={'original_name': '塞巴...手提包相關聯。'}, input_type=dict]
    For further information visit https://errors.pydantic.dev/2.11/v/missing
2025-09-09 18:35:12 - [WARNING] - [512280345618546699] 工具 'add_or_update_world_lore' 首次執行失敗: 2 validation errors for AddOrUpdateWorldLoreArgs
lore_key
  Field required [type=missing, input_value={'original_name': '性神...祝福』或體驗。'}, input_type=dict]
    For further information visit https://errors.pydantic.dev/2.11/v/missing
standardized_name
  Field required [type=missing, input_value={'original_name': '性神...祝福』或體驗。'}, input_type=dict]
    For further information visit https://errors.pydantic.dev/2.11/v/missing。啟動【委婉化重試】策略...
2025-09-09 18:35:13 - [INFO] - [512280345618546699] (重試) 已生成安全參數 'content': '描述一個與性神城相關的場景，其中包含神聖祝福的元素。'。正在用其重試工具 'add_or_update_world_lore'...
2025-09-09 18:35:13 - [ERROR] - [512280345618546699] 任務失敗 (重試後): for add_or_update_world_lore: 2 validation errors for AddOrUpdateWorldLoreArgs
lore_key
  Field required [type=missing, input_value={'original_name': '性神...聖祝福的元素。'}, input_type=dict]
    For further information visit https://errors.pydantic.dev/2.11/v/missing
standardized_name
  Field required [type=missing, input_value={'original_name': '性神...聖祝福的元素。'}, input_type=dict]
    For further information visit https://errors.pydantic.dev/2.11/v/missing
Traceback (most recent call last):
  File "D:\DINO\SD\ComfyUI\personal_server\ai_lover_service\src\ai_core.py", line 3011, in _execute_tool_call_plan
    validated_retry_args = tool_to_execute.args_schema.model_validate(retry_params)
  File "C:\Users\USER\AppData\Local\Programs\Python\Python310\lib\site-packages\pydantic\main.py", line 705, in model_validate
    return cls.__pydantic_validator__.validate_python(
pydantic_core._pydantic_core.ValidationError: 2 validation errors for AddOrUpdateWorldLoreArgs
lore_key
  Field required [type=missing, input_value={'original_name': '性神...聖祝福的元素。'}, input_type=dict]
    For further information visit https://errors.pydantic.dev/2.11/v/missing
standardized_name
  Field required [type=missing, input_value={'original_name': '性神...聖祝福的元素。'}, input_type=dict]
    For further information visit https://errors.pydantic.dev/2.11/v/missing
2025-09-09 18:35:13 - [INFO] - --- [512280345618546699] 場景擴展計畫執行完畢 ---
2025-09-09 18:35:13 - [INFO] - [512280345618546699] 背景任務的工具上下文已清理。
