### AI Lover Log - Last updated at 2025-09-17T23:34:30.250938 ###

  File "C:\Users\USER\AppData\Local\Programs\Python\Python310\lib\site-packages\pydantic\main.py", line 705, in model_validate
    return cls.__pydantic_validator__.validate_python(
pydantic_core._pydantic_core.ValidationError: 2 validation errors for WorldGenesisResult
location_path
  Field required [type=missing, input_value={'location': ['艾欧尼...守护者之一。'}]}, input_type=dict]
    For further information visit https://errors.pydantic.dev/2.11/v/missing
location_info
  Field required [type=missing, input_value={'location': ['艾欧尼...守护者之一。'}]}, input_type=dict]
    For further information visit https://errors.pydantic.dev/2.11/v/missing

During handling of the above exception, another exception occurred:

Traceback (most recent call last):
  File "D:\DINO\SD\ComfyUI\personal_server\ai_lover_service\src\discord_bot.py", line 800, in finalize_setup
    await ai_instance.generate_world_genesis()
  File "D:\DINO\SD\ComfyUI\personal_server\ai_lover_service\src\ai_core.py", line 666, in generate_world_genesis
    raise Exception(f"世界創世返回了無效的JSON格式或內容: {e}")
Exception: 世界創世返回了無效的JSON格式或內容: 2 validation errors for WorldGenesisResult
location_path
  Field required [type=missing, input_value={'location': ['艾欧尼...守护者之一。'}]}, input_type=dict]
    For further information visit https://errors.pydantic.dev/2.11/v/missing
location_info
  Field required [type=missing, input_value={'location': ['艾欧尼...守护者之一。'}]}, input_type=dict]
    For further information visit https://errors.pydantic.dev/2.11/v/missing
2025-09-17 23:20:49 - [INFO] - 所有持久化 UI 視圖已成功註冊。
2025-09-17 23:20:49 - [INFO] - Discord Bot is ready and commands are synced!
2025-09-17 23:20:52 - [INFO] - 【健康檢查 & Keep-Alive】背景任務已啟動。
2025-09-17 23:20:52 - [INFO] - Logged in as AI#4450 (ID: 1358417100250808531)
2025-09-17 23:20:53 - [INFO] - 已成功發送啟動成功通知給管理員。
2025-09-17 23:23:31 - [INFO] - [512280345618546699] 後台重置任務開始...
2025-09-17 23:23:34 - [INFO] - [512280345618546699] (UI Event) Persistent 'StartSetupView' button clicked.
2025-09-17 23:23:39 - [INFO] - [512280345618546699] (UI Event) WorldSettingsModal submitted. is_setup_flow: True
2025-09-17 23:23:39 - [INFO] - 使用者 512280345618546699 沒有活躍的 AI 實例，嘗試創建...
2025-09-17 23:23:39 - [INFO] - [512280345618546699] 處於設定流程中，即使資料庫無記錄，也創建一個臨時的記憶體實例。
2025-09-17 23:23:39 - [INFO] - [512280345618546699] 核心數據模板 'world_snapshot_template.txt' 已成功加載。
2025-09-17 23:23:39 - [INFO] - [512280345618546699] 核心協議模板 '00_supreme_directive.txt' 已成功加載並設置。
2025-09-17 23:23:39 - [INFO] - [512280345618546699] 已精簡模組化提示詞加載，只保留核心協議。
2025-09-17 23:23:39 - [INFO] - [512280345618546699] 正在創建模型 'gemini-2.5-flash-lite' 實例 (API Key index: 0)
2025-09-17 23:23:39 - [INFO] - [512280345618546699] 正在創建 Embedding 模型實例 (API Key index: 1)
2025-09-17 23:23:39 - [INFO] - [512280345618546699] (Retriever Builder) 已從 SQL 加載 0 條記憶。
2025-09-17 23:23:39 - [INFO] - [512280345618546699] (Retriever Builder) 記憶庫為空，BM25 備援檢索器為空。
2025-09-17 23:23:40 - [INFO] - [512280345618546699] (Retriever Builder) ChromaDB 主要檢索器構建成功。
2025-09-17 23:23:40 - [INFO] - [512280345618546699] (Retriever Builder) 混合檢索器構建成功。
2025-09-17 23:23:40 - [INFO] - [512280345618546699] 所有構建鏈的前置資源已準備就緒。
2025-09-17 23:23:40 - [INFO] - [512280345618546699] 接收到 profile 更新請求: ['world_settings']
2025-09-17 23:23:40 - [WARNING] - [512280345618546699] 在持久化更新時找不到使用者資料，將創建新記錄。
2025-09-17 23:23:40 - [INFO] - [512280345618546699] Profile 更新並持久化成功。
2025-09-17 23:23:42 - [INFO] - [512280345618546699] (UI Event) Persistent 'ContinueToUserSetupView' button clicked.
2025-09-17 23:23:50 - [INFO] - [512280345618546699] (UI Event) CharacterSettingsModal submitted for profile_type: 'user', is_setup_flow: True
2025-09-17 23:23:51 - [INFO] - [512280345618546699] 接收到 profile 更新請求: ['user_profile']
2025-09-17 23:23:51 - [INFO] - [512280345618546699] Profile 更新並持久化成功。
2025-09-17 23:23:52 - [INFO] - [512280345618546699] (UI Event) Persistent 'ContinueToAiSetupView' button clicked.
2025-09-17 23:24:13 - [INFO] - [512280345618546699] (UI Event) CharacterSettingsModal submitted for profile_type: 'ai', is_setup_flow: True
2025-09-17 23:24:13 - [INFO] - [512280345618546699] 接收到 profile 更新請求: ['ai_profile']
2025-09-17 23:24:13 - [INFO] - [512280345618546699] Profile 更新並持久化成功。
2025-09-17 23:24:15 - [INFO] - [512280345618546699] (UI Event) Persistent 'ContinueToCanonSetupView' finalize button clicked.
2025-09-17 23:24:15 - [INFO] - [512280345618546699] (UI Event) finalize_setup 被觸發。Canon provided: False
2025-09-17 23:24:16 - [INFO] - [512280345618546699] [/start 流程 1/4] 正在處理世界聖經...
2025-09-17 23:24:16 - [INFO] - [512280345618546699] [/start] 未提供世界聖經文本，跳過處理。
2025-09-17 23:24:16 - [INFO] - [512280345618546699] [/start 流程 1/4] 世界聖經處理完畢。
2025-09-17 23:24:18 - [INFO] - [512280345618546699] [/start 流程 2/4] 正在補完角色檔案...
2025-09-17 23:24:18 - [INFO] - [512280345618546699] --- 開始嘗試模型: 'gemini-2.5-flash-lite' (優先級 1/1) ---
2025-09-17 23:24:18 - [INFO] - [512280345618546699] --- 開始嘗試模型: 'gemini-2.5-flash-lite' (優先級 1/1) ---
2025-09-17 23:24:25 - [INFO] - [512280345618546699] 接收到 profile 更新請求: ['user_profile', 'ai_profile']
2025-09-17 23:24:25 - [INFO] - [512280345618546699] Profile 更新並持久化成功。
2025-09-17 23:24:25 - [INFO] - [512280345618546699] [/start 流程 2/4] 角色檔案補完畢。
2025-09-17 23:24:27 - [INFO] - [512280345618546699] [/start 流程 3/4] 正在生成世界創世資訊...
2025-09-17 23:24:27 - [INFO] - [512280345618546699] --- 開始嘗試模型: 'gemini-2.5-flash-lite' (優先級 1/1) ---
2025-09-17 23:24:34 - [INFO] - [512280345618546699] 接收到 profile 更新請求: ['game_state']
2025-09-17 23:24:34 - [INFO] - [512280345618546699] Profile 更新並持久化成功。
2025-09-17 23:24:34 - [INFO] - [512280345618546699] [/start 流程 3/4] 世界創世資訊生成完畢。
2025-09-17 23:24:36 - [INFO] - [512280345618546699] [/start 流程 4/4] 正在生成開場白...
2025-09-17 23:24:36 - [INFO] - [512280345618546699] --- 開始嘗試模型: 'gemini-2.5-pro' (優先級 1/3) ---
2025-09-17 23:26:17 - [ERROR] - [512280345618546699] 在直接Gemini API呼叫期間發生未知錯誤: InternalServerError: 500 An internal error has occurred. Please retry or report in https://developers.generativeai.google/guide/troubleshooting
Traceback (most recent call last):
  File "D:\DINO\SD\ComfyUI\personal_server\ai_lover_service\src\ai_core.py", line 487, in _direct_gemini_generate
    response = await model.generate_content_async(
  File "C:\Users\USER\AppData\Local\Programs\Python\Python310\lib\site-packages\google\generativeai\generative_models.py", line 385, in generate_content_async
    response = await self._async_client.generate_content(
  File "C:\Users\USER\AppData\Local\Programs\Python\Python310\lib\site-packages\google\ai\generativelanguage_v1beta\services\generative_service\async_client.py", line 440, in generate_content
    response = await rpc(
  File "C:\Users\USER\AppData\Local\Programs\Python\Python310\lib\site-packages\google\api_core\retry\retry_unary_async.py", line 231, in retry_wrapped_func
    return await retry_target(
  File "C:\Users\USER\AppData\Local\Programs\Python\Python310\lib\site-packages\google\api_core\retry\retry_unary_async.py", line 163, in retry_target
    next_sleep = _retry_error_helper(
  File "C:\Users\USER\AppData\Local\Programs\Python\Python310\lib\site-packages\google\api_core\retry\retry_base.py", line 214, in _retry_error_helper
    raise final_exc from source_exc
  File "C:\Users\USER\AppData\Local\Programs\Python\Python310\lib\site-packages\google\api_core\retry\retry_unary_async.py", line 158, in retry_target
    return await target()
  File "C:\Users\USER\AppData\Local\Programs\Python\Python310\lib\site-packages\google\api_core\grpc_helpers_async.py", line 88, in __await__
    raise exceptions.from_grpc_error(rpc_error) from rpc_error
google.api_core.exceptions.InternalServerError: 500 An internal error has occurred. Please retry or report in https://developers.generativeai.google/guide/troubleshooting
2025-09-17 23:26:17 - [INFO] - [512280345618546699] [/start 流程 4/4] 開場白生成完畢。
2025-09-17 23:26:17 - [INFO] - [512280345618546699] /start 流程：正在向使用者私訊發送開場白...
2025-09-17 23:26:18 - [INFO] - [512280345618546699] /start 流程：開場白發送完畢。設定流程成功結束。
2025-09-17 23:34:16 - [INFO] - 所有持久化 UI 視圖已成功註冊。
2025-09-17 23:34:16 - [INFO] - Discord Bot is ready and commands are synced!
2025-09-17 23:34:20 - [INFO] - 【健康檢查 & Keep-Alive】背景任務已啟動。
2025-09-17 23:34:20 - [INFO] - Logged in as AI#4450 (ID: 1358417100250808531)
2025-09-17 23:34:21 - [INFO] - 已成功發送啟動成功通知給管理員。
