### AI Lover Log - Last updated at 2025-10-12T08:19:01.849143 ###

2025-10-11 23:04:47 - [INFO] - [512280345618546699] [智能聚合] 已成功轉換並添加 LORE: '挫敗感'
2025-10-11 23:04:47 - [INFO] - [512280345618546699] [智能聚合] 已成功轉換並添加 LORE: 'Enhancement'
2025-10-11 23:04:47 - [INFO] - [512280345618546699] [後台創世] 步驟 3/3: 數據準備完成，正在使用 67 條文檔觸發 RAG 索引創始構建...
2025-10-11 23:04:47 - [INFO] - [512280345618546699] (Retriever Builder) 進入外部文檔注入模式，使用 67 條傳入文檔，準備使用 67 條文檔進行構建...
2025-10-11 23:06:25 - [INFO] - [512280345618546699] 後台創世流程結束，狀態鎖已釋放。
2025-10-12 00:06:51 - [INFO] - 正在加載核心 Cog (core_cog)...
2025-10-12 00:06:58 - [INFO] - ✅ 核心 Cog (core_cog) 已加載，並且所有持久化視圖已成功註冊。
2025-10-12 00:06:58 - [INFO] - ✅ 核心 Cog 加載成功。
2025-10-12 00:06:58 - [INFO] - 正在全域同步應用程式指令...
2025-10-12 00:06:59 - [INFO] - ✅ 指令已全域同步！
2025-10-12 00:06:59 - [INFO] - Discord Bot setup hook finished!
2025-10-12 00:07:02 - [INFO] - Logged in as AI#4450 (ID: 1358417100250808531)
2025-10-12 00:07:03 - [INFO] - 已成功發送啟動成功通知給管理員。
2025-10-12 00:11:37 - [INFO] - [512280345618546699] [Data Reset] 正在啟動使用者資料重置流程...
2025-10-12 00:11:38 - [INFO] - [512280345618546699] [Data Reset] 所有相關的資料庫記錄已成功刪除。
2025-10-12 00:11:38 - [INFO] - [512280345618546699] [Data Reset] 向量儲存目錄 'D:\DINO\SD\ComfyUI\personal_server\ai_lover_service\data\vector_stores\512280345618546699' 已成功刪除。
2025-10-12 00:11:38 - [INFO] - [512280345618546699] [Data Reset] 資料重置流程已全部完成。
2025-10-12 00:11:40 - [INFO] - [512280345618546699] (UI Event) Persistent 'StartSetupView' button clicked.
2025-10-12 00:11:45 - [INFO] - 使用者 512280345618546699 沒有活躍的 AI 實例，嘗試創建...
2025-10-12 00:11:45 - [INFO] - [512280345618546699] 處於設定流程中，即使資料庫無記錄，也創建一個臨時的記憶體實例。
2025-10-12 00:11:45 - [INFO] - [512280345618546699] 核心數據模板 'world_snapshot_template.txt' 已成功加載。
2025-10-12 00:11:45 - [INFO] - [512280345618546699] 核心協議 '00_supreme_directive.txt' 已成功加載。
2025-10-12 00:11:45 - [INFO] - ℹ️ [Embedding Loader] 正在啟動【純本地 RAG】Embedding 引擎...
2025-10-12 00:11:45 - [INFO] -    - 檢測到本地模型路徑，正在嘗試從 'D:\DINO\SD\ComfyUI\personal_server\ai_lover_service\models\stella-base-zh-v2' 加載...
2025-10-12 00:11:54 - [INFO] - ✅ [Embedding Loader] 純本地 Embedding 模型成功加載。
2025-10-12 00:11:54 - [INFO] - [512280345618546699] 所有輕量級前置資源已準備就緒 (RAG 創建已延遲)。
2025-10-12 00:11:54 - [INFO] - [512280345618546699] 接收到 profile 更新請求: ['world_settings']
2025-10-12 00:11:54 - [WARNING] - [512280345618546699] 在持久化更新時找不到使用者資料，將創建新記錄。
2025-10-12 00:11:54 - [INFO] - [512280345618546699] Profile 更新並持久化成功。
2025-10-12 00:11:56 - [INFO] - [512280345618546699] (UI Event) Persistent 'ContinueToUserSetupView' button clicked.
2025-10-12 00:12:06 - [INFO] - [512280345618546699] (UI Event) CharacterSettingsModal submitted for profile_type: 'user', is_setup_flow: True
2025-10-12 00:12:07 - [INFO] - [512280345618546699] 接收到 profile 更新請求: ['user_profile']
2025-10-12 00:12:08 - [INFO] - [512280345618546699] Profile 更新並持久化成功。
2025-10-12 00:12:14 - [INFO] - [512280345618546699] (UI Event) Persistent 'ContinueToAiSetupView' button clicked.
2025-10-12 00:12:29 - [INFO] - [512280345618546699] (UI Event) CharacterSettingsModal submitted for profile_type: 'ai', is_setup_flow: True
2025-10-12 00:12:29 - [INFO] - [512280345618546699] 接收到 profile 更新請求: ['ai_profile']
2025-10-12 00:12:29 - [INFO] - [512280345618546699] Profile 更新並持久化成功。
2025-10-12 00:12:31 - [INFO] - [512280345618546699] [創世流程] 檔案上傳開始，已設定 active_setups 狀態鎖。
2025-10-12 00:12:38 - [INFO] - [512280345618546699] (on_message) 偵測到用戶處於活躍的創世流程中，已忽略常規訊息 '...' 以防止競爭。
2025-10-12 00:12:41 - [INFO] - [512280345618546699] [創世流程 v66.2] 啟動【本地預處理 + 智能聚合】流程...
2025-10-12 00:12:41 - [INFO] - [512280345618546699] [後台創世] 步驟 1/3: 正在調用本地 Ollama 模型進行無審查預解析...
2025-10-12 00:12:41 - [INFO] - [512280345618546699] [本地執行單元] 正在啟動 v4.0 潤色/備援流程...
2025-10-12 00:12:41 - [WARNING] - [512280345618546699] [本地執行單元-LLM] 🔥 LLM 批次化潤色失敗: 'str' object has no attribute 'keys'
Traceback (most recent call last):
  File "D:\DINO\SD\ComfyUI\personal_server\ai_lover_service\src\ai_core.py", line 1856, in _invoke_local_ollama_parser
    all_entities = list(aggregated_facts_map.keys())
AttributeError: 'str' object has no attribute 'keys'
2025-10-12 00:12:41 - [WARNING] - [512280345618546699] [本地執行單元-備援] 正在觸發【純程式碼備援方案】，以確保數據保真度...
2025-10-12 00:12:41 - [ERROR] - [512280345618546699] 後台創世流程發生嚴重錯誤: 'str' object has no attribute 'items'
Traceback (most recent call last):
  File "D:\DINO\SD\ComfyUI\personal_server\ai_lover_service\src\cogs\core_cog.py", line 1132, in _perform_full_setup_flow
    parsed_canon = await ai_instance._invoke_local_ollama_parser(canon_text)
  File "D:\DINO\SD\ComfyUI\personal_server\ai_lover_service\src\ai_core.py", line 1916, in _invoke_local_ollama_parser
    for name, facts in aggregated_facts_map.items():
AttributeError: 'str' object has no attribute 'items'
2025-10-12 00:12:41 - [INFO] - [512280345618546699] 後台創世流程結束，狀態鎖已釋放。
2025-10-12 00:17:53 - [INFO] - 正在加載核心 Cog (core_cog)...
2025-10-12 00:17:56 - [INFO] - ✅ 核心 Cog (core_cog) 已加載，並且所有持久化視圖已成功註冊。
2025-10-12 00:17:56 - [INFO] - ✅ 核心 Cog 加載成功。
2025-10-12 00:17:56 - [INFO] - 正在全域同步應用程式指令...
2025-10-12 00:17:57 - [INFO] - ✅ 指令已全域同步！
2025-10-12 00:17:57 - [INFO] - Discord Bot setup hook finished!
2025-10-12 00:18:00 - [INFO] - Logged in as AI#4450 (ID: 1358417100250808531)
2025-10-12 00:18:00 - [INFO] - 已成功發送啟動成功通知給管理員。
2025-10-12 00:18:52 - [INFO] - [512280345618546699] [Data Reset] 正在啟動使用者資料重置流程...
2025-10-12 00:18:52 - [INFO] - [512280345618546699] [Data Reset] 所有相關的資料庫記錄已成功刪除。
2025-10-12 00:18:52 - [INFO] - [512280345618546699] [Data Reset] 向量儲存目錄 'D:\DINO\SD\ComfyUI\personal_server\ai_lover_service\data\vector_stores\512280345618546699' 已成功刪除。
2025-10-12 00:18:52 - [INFO] - [512280345618546699] [Data Reset] 資料重置流程已全部完成。
2025-10-12 00:18:54 - [INFO] - [512280345618546699] (UI Event) Persistent 'StartSetupView' button clicked.
2025-10-12 00:18:58 - [INFO] - 使用者 512280345618546699 沒有活躍的 AI 實例，嘗試創建...
2025-10-12 00:18:58 - [INFO] - [512280345618546699] 處於設定流程中，即使資料庫無記錄，也創建一個臨時的記憶體實例。
2025-10-12 00:18:58 - [INFO] - [512280345618546699] 核心數據模板 'world_snapshot_template.txt' 已成功加載。
2025-10-12 00:18:58 - [INFO] - [512280345618546699] 核心協議 '00_supreme_directive.txt' 已成功加載。
2025-10-12 00:18:58 - [INFO] - ℹ️ [Embedding Loader] 正在啟動【純本地 RAG】Embedding 引擎...
2025-10-12 00:18:58 - [INFO] -    - 檢測到本地模型路徑，正在嘗試從 'D:\DINO\SD\ComfyUI\personal_server\ai_lover_service\models\stella-base-zh-v2' 加載...
2025-10-12 00:19:01 - [INFO] - ✅ [Embedding Loader] 純本地 Embedding 模型成功加載。
2025-10-12 00:19:01 - [INFO] - [512280345618546699] 所有輕量級前置資源已準備就緒 (RAG 創建已延遲)。
2025-10-12 00:19:01 - [INFO] - [512280345618546699] 接收到 profile 更新請求: ['world_settings']
2025-10-12 00:19:01 - [WARNING] - [512280345618546699] 在持久化更新時找不到使用者資料，將創建新記錄。
2025-10-12 00:19:01 - [INFO] - [512280345618546699] Profile 更新並持久化成功。
2025-10-12 00:19:02 - [INFO] - [512280345618546699] (UI Event) Persistent 'ContinueToUserSetupView' button clicked.
2025-10-12 00:19:10 - [INFO] - [512280345618546699] (UI Event) CharacterSettingsModal submitted for profile_type: 'user', is_setup_flow: True
2025-10-12 00:19:10 - [INFO] - [512280345618546699] 接收到 profile 更新請求: ['user_profile']
2025-10-12 00:19:10 - [INFO] - [512280345618546699] Profile 更新並持久化成功。
2025-10-12 00:19:12 - [INFO] - [512280345618546699] (UI Event) Persistent 'ContinueToAiSetupView' button clicked.
2025-10-12 00:19:21 - [INFO] - [512280345618546699] (UI Event) CharacterSettingsModal submitted for profile_type: 'ai', is_setup_flow: True
2025-10-12 00:19:22 - [INFO] - [512280345618546699] 接收到 profile 更新請求: ['ai_profile']
2025-10-12 00:19:22 - [INFO] - [512280345618546699] Profile 更新並持久化成功。
2025-10-12 00:19:24 - [INFO] - [512280345618546699] [創世流程] 檔案上傳開始，已設定 active_setups 狀態鎖。
2025-10-12 00:19:29 - [INFO] - [512280345618546699] (on_message) 偵測到用戶處於活躍的創世流程中，已忽略常規訊息 '...' 以防止競爭。
2025-10-12 00:19:32 - [INFO] - [512280345618546699] [創世流程 v66.2] 啟動【本地預處理 + 智能聚合】流程...
2025-10-12 00:19:32 - [INFO] - [512280345618546699] [後台創世] 步驟 1/3: 正在調用本地 Ollama 模型進行無審查預解析...
2025-10-12 00:19:32 - [WARNING] - [512280345618546699] [本地执行单元] 检测到不推荐的直接文本输入！这表明外部调用方式已过时。
2025-10-12 00:19:32 - [WARNING] - [512280345618546699] [本地执行单元] 正在自动重定向到【终极架构v4.1】总指挥官进行处理...
2025-10-12 00:19:32 - [INFO] - [512280345618546699] [数据入口-轨道B] 正在启动【终极架构v4.1：上下文隔离】LORE解析管线...
2025-10-12 00:26:34 - [INFO] - [512280345618546699] [总指挥-P1&3] ✅ 程式码提取与融合完成，共计 333 个唯一实体。
2025-10-12 00:26:34 - [INFO] - [512280345618546699] [总指挥-P4] 正在将融合情报提交至本地执行单元进行最终处理...
2025-10-12 00:26:34 - [INFO] - [512280345618546699] [本地执行单元] 正在启动 v5.0 润色/备援流程...
2025-10-12 00:26:34 - [INFO] - [512280345618546699] [本地执行单元-LLM] 正在处理批次 1/67...
2025-10-12 00:29:33 - [INFO] - [512280345618546699] [本地执行单元-LLM] 正在处理批次 2/67...
2025-10-12 00:34:33 - [WARNING] - [512280345618546699] [本地执行单元-LLM] 🔥 LLM 批次化润色失败: 
Traceback (most recent call last):
  File "C:\Users\USER\AppData\Local\Programs\Python\Python310\lib\site-packages\httpx\_transports\default.py", line 69, in map_httpcore_exceptions
    yield
  File "C:\Users\USER\AppData\Local\Programs\Python\Python310\lib\site-packages\httpx\_transports\default.py", line 373, in handle_async_request
    resp = await self._pool.handle_async_request(req)
  File "C:\Users\USER\AppData\Local\Programs\Python\Python310\lib\site-packages\httpcore\_async\connection_pool.py", line 256, in handle_async_request
    raise exc from None
  File "C:\Users\USER\AppData\Local\Programs\Python\Python310\lib\site-packages\httpcore\_async\connection_pool.py", line 236, in handle_async_request
    response = await connection.handle_async_request(
  File "C:\Users\USER\AppData\Local\Programs\Python\Python310\lib\site-packages\httpcore\_async\connection.py", line 103, in handle_async_request
    return await self._connection.handle_async_request(request)
  File "C:\Users\USER\AppData\Local\Programs\Python\Python310\lib\site-packages\httpcore\_async\http11.py", line 136, in handle_async_request
    raise exc
  File "C:\Users\USER\AppData\Local\Programs\Python\Python310\lib\site-packages\httpcore\_async\http11.py", line 106, in handle_async_request
    ) = await self._receive_response_headers(**kwargs)
  File "C:\Users\USER\AppData\Local\Programs\Python\Python310\lib\site-packages\httpcore\_async\http11.py", line 177, in _receive_response_headers
    event = await self._receive_event(timeout=timeout)
  File "C:\Users\USER\AppData\Local\Programs\Python\Python310\lib\site-packages\httpcore\_async\http11.py", line 217, in _receive_event
    data = await self._network_stream.read(
  File "C:\Users\USER\AppData\Local\Programs\Python\Python310\lib\site-packages\httpcore\_backends\anyio.py", line 32, in read
    with map_exceptions(exc_map):
  File "C:\Users\USER\AppData\Local\Programs\Python\Python310\lib\contextlib.py", line 153, in __exit__
    self.gen.throw(typ, value, traceback)
  File "C:\Users\USER\AppData\Local\Programs\Python\Python310\lib\site-packages\httpcore\_exceptions.py", line 14, in map_exceptions
    raise to_exc(exc) from exc
httpcore.ReadTimeout

The above exception was the direct cause of the following exception:

Traceback (most recent call last):
  File "D:\DINO\SD\ComfyUI\personal_server\ai_lover_service\src\ai_core.py", line 1905, in _invoke_local_ollama_parser
    response = await client.post("http://localhost:11434/api/generate", json=payload)
  File "C:\Users\USER\AppData\Local\Programs\Python\Python310\lib\site-packages\httpx\_client.py", line 1892, in post
    return await self.request(
  File "C:\Users\USER\AppData\Local\Programs\Python\Python310\lib\site-packages\httpx\_client.py", line 1574, in request
    return await self.send(request, auth=auth, follow_redirects=follow_redirects)
  File "C:\Users\USER\AppData\Local\Programs\Python\Python310\lib\site-packages\httpx\_client.py", line 1661, in send
    response = await self._send_handling_auth(
  File "C:\Users\USER\AppData\Local\Programs\Python\Python310\lib\site-packages\httpx\_client.py", line 1689, in _send_handling_auth
    response = await self._send_handling_redirects(
  File "C:\Users\USER\AppData\Local\Programs\Python\Python310\lib\site-packages\httpx\_client.py", line 1726, in _send_handling_redirects
    response = await self._send_single_request(request)
  File "C:\Users\USER\AppData\Local\Programs\Python\Python310\lib\site-packages\httpx\_client.py", line 1763, in _send_single_request
    response = await transport.handle_async_request(request)
  File "C:\Users\USER\AppData\Local\Programs\Python\Python310\lib\site-packages\httpx\_transports\default.py", line 372, in handle_async_request
    with map_httpcore_exceptions():
  File "C:\Users\USER\AppData\Local\Programs\Python\Python310\lib\contextlib.py", line 153, in __exit__
    self.gen.throw(typ, value, traceback)
  File "C:\Users\USER\AppData\Local\Programs\Python\Python310\lib\site-packages\httpx\_transports\default.py", line 86, in map_httpcore_exceptions
    raise mapped_exc(message) from exc
httpx.ReadTimeout
2025-10-12 00:34:33 - [WARNING] - [512280345618546699] [本地执行单元-备援] 正在觸發【純程式碼備援方案】，以确保数据保真度...
2025-10-12 00:34:34 - [INFO] - [512280345618546699] [本地执行单元-备援] ✅ 純程式碼備援执行完毕。
2025-10-12 00:34:34 - [INFO] - [512280345618546699] [总指挥-P5] 正在将最终的 333 个LORE档案持久化到资料库...
2025-10-12 00:35:08 - [INFO] - [512280345618546699] [数据入口-轨道B] ✅ 【终极架构v4.1：上下文隔离】LORE解析管线执行完毕。
2025-10-12 00:35:08 - [INFO] - [512280345618546699] [後台創世] 步驟 2/3: 本地預解析成功，正在執行智能聚合...
2025-10-12 00:35:08 - [ERROR] - [512280345618546699] 後台創世流程發生嚴重錯誤: 'list' object has no attribute 'npc_profiles'
Traceback (most recent call last):
  File "D:\DINO\SD\ComfyUI\personal_server\ai_lover_service\src\cogs\core_cog.py", line 1153, in _perform_full_setup_flow
    if parsed_canon.npc_profiles: all_lores_to_process.extend([(p, 'characterprofile') for p in parsed_canon.npc_profiles])
AttributeError: 'list' object has no attribute 'npc_profiles'
2025-10-12 00:35:09 - [INFO] - [512280345618546699] 後台創世流程結束，狀態鎖已釋放。
2025-10-12 00:37:57 - [INFO] - 正在加載核心 Cog (core_cog)...
2025-10-12 00:37:57 - [ERROR] - 🔥 核心 Cog 加載失敗: Extension 'src.cogs.core_cog' raised an error: SyntaxError: unmatched ')' (core_cog.py, line 1132)
Traceback (most recent call last):
  File "C:\Users\USER\AppData\Local\Programs\Python\Python310\lib\site-packages\discord\ext\commands\bot.py", line 935, in _load_from_module_spec
    spec.loader.exec_module(lib)  # type: ignore
  File "<frozen importlib._bootstrap_external>", line 879, in exec_module
  File "<frozen importlib._bootstrap_external>", line 1017, in get_code
  File "<frozen importlib._bootstrap_external>", line 947, in source_to_code
  File "<frozen importlib._bootstrap>", line 241, in _call_with_frames_removed
  File "D:\DINO\SD\ComfyUI\personal_server\ai_lover_service\src\cogs\core_cog.py", line 1132
    pafinal_profiles = await ai_instance.parse_and_create_lore_from_canon(canon_text)canon_text)
                                                                                               ^
SyntaxError: unmatched ')'

The above exception was the direct cause of the following exception:

Traceback (most recent call last):
  File "D:\DINO\SD\ComfyUI\personal_server\ai_lover_service\src\discord_bot.py", line 41, in setup_hook
    await self.load_extension("src.cogs.core_cog")
  File "C:\Users\USER\AppData\Local\Programs\Python\Python310\lib\site-packages\discord\ext\commands\bot.py", line 1013, in load_extension
    await self._load_from_module_spec(spec, name)
  File "C:\Users\USER\AppData\Local\Programs\Python\Python310\lib\site-packages\discord\ext\commands\bot.py", line 938, in _load_from_module_spec
    raise errors.ExtensionFailed(key, e) from e
discord.ext.commands.errors.ExtensionFailed: Extension 'src.cogs.core_cog' raised an error: SyntaxError: unmatched ')' (core_cog.py, line 1132)
2025-10-12 00:47:04 - [INFO] - 正在加載核心 Cog (core_cog)...
2025-10-12 00:47:04 - [ERROR] - 🔥 核心 Cog 加載失敗: Extension 'src.cogs.core_cog' raised an error: SyntaxError: unmatched ')' (core_cog.py, line 1132)
Traceback (most recent call last):
  File "C:\Users\USER\AppData\Local\Programs\Python\Python310\lib\site-packages\discord\ext\commands\bot.py", line 935, in _load_from_module_spec
    spec.loader.exec_module(lib)  # type: ignore
  File "<frozen importlib._bootstrap_external>", line 879, in exec_module
  File "<frozen importlib._bootstrap_external>", line 1017, in get_code
  File "<frozen importlib._bootstrap_external>", line 947, in source_to_code
  File "<frozen importlib._bootstrap>", line 241, in _call_with_frames_removed
  File "D:\DINO\SD\ComfyUI\personal_server\ai_lover_service\src\cogs\core_cog.py", line 1132
    pafinal_profiles = await ai_instance.parse_and_create_lore_from_canon(canon_text)canon_text)
                                                                                               ^
SyntaxError: unmatched ')'

The above exception was the direct cause of the following exception:

Traceback (most recent call last):
  File "D:\DINO\SD\ComfyUI\personal_server\ai_lover_service\src\discord_bot.py", line 41, in setup_hook
    await self.load_extension("src.cogs.core_cog")
  File "C:\Users\USER\AppData\Local\Programs\Python\Python310\lib\site-packages\discord\ext\commands\bot.py", line 1013, in load_extension
    await self._load_from_module_spec(spec, name)
  File "C:\Users\USER\AppData\Local\Programs\Python\Python310\lib\site-packages\discord\ext\commands\bot.py", line 938, in _load_from_module_spec
    raise errors.ExtensionFailed(key, e) from e
discord.ext.commands.errors.ExtensionFailed: Extension 'src.cogs.core_cog' raised an error: SyntaxError: unmatched ')' (core_cog.py, line 1132)
2025-10-12 00:49:25 - [INFO] - 正在加載核心 Cog (core_cog)...
2025-10-12 00:49:31 - [INFO] - ✅ 核心 Cog (core_cog) 已加載，並且所有持久化視圖已成功註冊。
2025-10-12 00:49:31 - [INFO] - ✅ 核心 Cog 加載成功。
2025-10-12 00:49:31 - [INFO] - 正在全域同步應用程式指令...
2025-10-12 00:49:31 - [INFO] - ✅ 指令已全域同步！
2025-10-12 00:49:31 - [INFO] - Discord Bot setup hook finished!
2025-10-12 00:49:34 - [INFO] - Logged in as AI#4450 (ID: 1358417100250808531)
2025-10-12 00:49:34 - [INFO] - 已成功發送啟動成功通知給管理員。
2025-10-12 01:05:19 - [INFO] - [512280345618546699] [Data Reset] 正在啟動使用者資料重置流程...
2025-10-12 01:05:20 - [INFO] - [512280345618546699] [Data Reset] 所有相關的資料庫記錄已成功刪除。
2025-10-12 01:05:20 - [INFO] - [512280345618546699] [Data Reset] 向量儲存目錄 'D:\DINO\SD\ComfyUI\personal_server\ai_lover_service\data\vector_stores\512280345618546699' 已成功刪除。
2025-10-12 01:05:20 - [INFO] - [512280345618546699] [Data Reset] 資料重置流程已全部完成。
2025-10-12 01:05:22 - [INFO] - [512280345618546699] (UI Event) Persistent 'StartSetupView' button clicked.
2025-10-12 01:05:27 - [INFO] - 使用者 512280345618546699 沒有活躍的 AI 實例，嘗試創建...
2025-10-12 01:05:27 - [INFO] - [512280345618546699] 處於設定流程中，即使資料庫無記錄，也創建一個臨時的記憶體實例。
2025-10-12 01:05:27 - [INFO] - [512280345618546699] 核心數據模板 'world_snapshot_template.txt' 已成功加載。
2025-10-12 01:05:27 - [INFO] - [512280345618546699] 核心協議 '00_supreme_directive.txt' 已成功加載。
2025-10-12 01:05:27 - [INFO] - ℹ️ [Embedding Loader] 正在啟動【純本地 RAG】Embedding 引擎...
2025-10-12 01:05:27 - [INFO] -    - 檢測到本地模型路徑，正在嘗試從 'D:\DINO\SD\ComfyUI\personal_server\ai_lover_service\models\stella-base-zh-v2' 加載...
2025-10-12 01:05:36 - [INFO] - ✅ [Embedding Loader] 純本地 Embedding 模型成功加載。
2025-10-12 01:05:36 - [INFO] - [512280345618546699] 所有輕量級前置資源已準備就緒 (RAG 創建已延遲)。
2025-10-12 01:05:36 - [INFO] - [512280345618546699] 接收到 profile 更新請求: ['world_settings']
2025-10-12 01:05:36 - [WARNING] - [512280345618546699] 在持久化更新時找不到使用者資料，將創建新記錄。
2025-10-12 01:05:36 - [INFO] - [512280345618546699] Profile 更新並持久化成功。
2025-10-12 01:05:38 - [INFO] - [512280345618546699] (UI Event) Persistent 'ContinueToUserSetupView' button clicked.
2025-10-12 01:05:47 - [INFO] - [512280345618546699] (UI Event) CharacterSettingsModal submitted for profile_type: 'user', is_setup_flow: True
2025-10-12 01:05:48 - [INFO] - [512280345618546699] 接收到 profile 更新請求: ['user_profile']
2025-10-12 01:05:48 - [INFO] - [512280345618546699] Profile 更新並持久化成功。
2025-10-12 01:05:49 - [INFO] - [512280345618546699] (UI Event) Persistent 'ContinueToAiSetupView' button clicked.
2025-10-12 01:05:59 - [INFO] - [512280345618546699] (UI Event) CharacterSettingsModal submitted for profile_type: 'ai', is_setup_flow: True
2025-10-12 01:05:59 - [INFO] - [512280345618546699] 接收到 profile 更新請求: ['ai_profile']
2025-10-12 01:05:59 - [INFO] - [512280345618546699] Profile 更新並持久化成功。
2025-10-12 01:06:01 - [INFO] - [512280345618546699] [創世流程] 檔案上傳開始，已設定 active_setups 狀態鎖。
2025-10-12 01:06:07 - [INFO] - [512280345618546699] (on_message) 偵測到用戶處於活躍的創世流程中，已忽略常規訊息 '...' 以防止競爭。
2025-10-12 01:06:10 - [ERROR] - [512280345618546699] 在等待檔案上傳時發生錯誤: BotCog._perform_full_setup_flow() got an unexpected keyword argument 'user'
Traceback (most recent call last):
  File "D:\DINO\SD\ComfyUI\personal_server\ai_lover_service\src\cogs\core_cog.py", line 310, in upload_canon
    asyncio.create_task(self.cog._perform_full_setup_flow(user=interaction.user, canon_text=content_text))
TypeError: BotCog._perform_full_setup_flow() got an unexpected keyword argument 'user'
2025-10-12 01:22:31 - [INFO] - 正在加載核心 Cog (core_cog)...
2025-10-12 01:22:37 - [INFO] - ✅ 核心 Cog (core_cog) 已加載，並且所有持久化視圖已成功註冊。
2025-10-12 01:22:37 - [INFO] - ✅ 核心 Cog 加載成功。
2025-10-12 01:22:37 - [INFO] - 正在全域同步應用程式指令...
2025-10-12 01:22:38 - [INFO] - ✅ 指令已全域同步！
2025-10-12 01:22:38 - [INFO] - Discord Bot setup hook finished!
2025-10-12 01:22:40 - [INFO] - Logged in as AI#4450 (ID: 1358417100250808531)
2025-10-12 01:22:42 - [INFO] - 已成功發送啟動成功通知給管理員。
2025-10-12 01:23:21 - [INFO] - 正在加載核心 Cog (core_cog)...
2025-10-12 01:23:25 - [INFO] - ✅ 核心 Cog (core_cog) 已加載，並且所有持久化視圖已成功註冊。
2025-10-12 01:23:25 - [INFO] - ✅ 核心 Cog 加載成功。
2025-10-12 01:23:25 - [INFO] - 正在全域同步應用程式指令...
2025-10-12 01:23:26 - [INFO] - ✅ 指令已全域同步！
2025-10-12 01:23:26 - [INFO] - Discord Bot setup hook finished!
2025-10-12 01:23:28 - [INFO] - Logged in as AI#4450 (ID: 1358417100250808531)
2025-10-12 01:23:29 - [INFO] - 已成功發送啟動成功通知給管理員。
2025-10-12 01:23:57 - [INFO] - [512280345618546699] [Data Reset] 正在啟動使用者資料重置流程...
2025-10-12 01:23:57 - [INFO] - [512280345618546699] [Data Reset] 所有相關的資料庫記錄已成功刪除。
2025-10-12 01:23:57 - [INFO] - [512280345618546699] [Data Reset] 向量儲存目錄 'D:\DINO\SD\ComfyUI\personal_server\ai_lover_service\data\vector_stores\512280345618546699' 已成功刪除。
2025-10-12 01:23:57 - [INFO] - [512280345618546699] [Data Reset] 資料重置流程已全部完成。
2025-10-12 01:23:59 - [INFO] - [512280345618546699] (UI Event) Persistent 'StartSetupView' button clicked.
2025-10-12 01:24:04 - [INFO] - 使用者 512280345618546699 沒有活躍的 AI 實例，嘗試創建...
2025-10-12 01:24:04 - [INFO] - [512280345618546699] 處於設定流程中，即使資料庫無記錄，也創建一個臨時的記憶體實例。
2025-10-12 01:24:04 - [INFO] - [512280345618546699] 核心數據模板 'world_snapshot_template.txt' 已成功加載。
2025-10-12 01:24:04 - [INFO] - [512280345618546699] 核心協議 '00_supreme_directive.txt' 已成功加載。
2025-10-12 01:24:04 - [INFO] - ℹ️ [Embedding Loader] 正在啟動【純本地 RAG】Embedding 引擎...
2025-10-12 01:24:04 - [INFO] -    - 檢測到本地模型路徑，正在嘗試從 'D:\DINO\SD\ComfyUI\personal_server\ai_lover_service\models\stella-base-zh-v2' 加載...
2025-10-12 01:24:12 - [INFO] - ✅ [Embedding Loader] 純本地 Embedding 模型成功加載。
2025-10-12 01:24:12 - [INFO] - [512280345618546699] 所有輕量級前置資源已準備就緒 (RAG 創建已延遲)。
2025-10-12 01:24:12 - [INFO] - [512280345618546699] 接收到 profile 更新請求: ['world_settings']
2025-10-12 01:24:12 - [WARNING] - [512280345618546699] 在持久化更新時找不到使用者資料，將創建新記錄。
2025-10-12 01:24:12 - [INFO] - [512280345618546699] Profile 更新並持久化成功。
2025-10-12 01:24:14 - [INFO] - [512280345618546699] (UI Event) Persistent 'ContinueToUserSetupView' button clicked.
2025-10-12 01:24:23 - [INFO] - [512280345618546699] (UI Event) CharacterSettingsModal submitted for profile_type: 'user', is_setup_flow: True
2025-10-12 01:24:23 - [INFO] - [512280345618546699] 接收到 profile 更新請求: ['user_profile']
2025-10-12 01:24:23 - [INFO] - [512280345618546699] Profile 更新並持久化成功。
2025-10-12 01:24:25 - [INFO] - [512280345618546699] (UI Event) Persistent 'ContinueToAiSetupView' button clicked.
2025-10-12 01:24:34 - [INFO] - [512280345618546699] (UI Event) CharacterSettingsModal submitted for profile_type: 'ai', is_setup_flow: True
2025-10-12 01:24:35 - [INFO] - [512280345618546699] 接收到 profile 更新請求: ['ai_profile']
2025-10-12 01:24:35 - [INFO] - [512280345618546699] Profile 更新並持久化成功。
2025-10-12 01:24:36 - [INFO] - [512280345618546699] [創世流程] 檔案上傳開始，已設定 active_setups 狀態鎖。
2025-10-12 01:24:43 - [INFO] - [512280345618546699] (on_message) 偵測到用戶處於活躍的創世流程中，已忽略常規訊息 '...' 以防止競爭。
2025-10-12 08:18:45 - [INFO] - 正在加載核心 Cog (core_cog)...
2025-10-12 08:18:55 - [INFO] - ✅ 核心 Cog (core_cog) 已加載，並且所有持久化視圖已成功註冊。
2025-10-12 08:18:55 - [INFO] - ✅ 核心 Cog 加載成功。
2025-10-12 08:18:55 - [INFO] - 正在全域同步應用程式指令...
2025-10-12 08:18:55 - [INFO] - ✅ 指令已全域同步！
2025-10-12 08:18:55 - [INFO] - Discord Bot setup hook finished!
2025-10-12 08:18:58 - [INFO] - Logged in as AI#4450 (ID: 1358417100250808531)
2025-10-12 08:18:59 - [INFO] - 已成功發送啟動成功通知給管理員。
